Workbook

Sheet Transfer Nilai
A1: Hasil Transfer Nilai Sementara
A2: Program Studi Sistem Informasi ITB STIKOM Bali
A4: Nama Calon Mhs | C4: : I Made Widya Kartika | G4: Prodi Asal | H4: : Manajemen Informatika
A5: Asal PT/Univ. | C5: : Universitas Pendidikan Ganesha | G5: Jenis | H5: : Lanjut Studi
A6: Fakultas | C6: : Teknik dan Kejuruan | G6: Tgl. Proses | H6: : 16 Oktober 2023
A7: Total SKS diakui | C7: =": "&D92&" SKS" -> : 81 SKS
A9: Matakuliah ITB STIKOM Bali | G9: Matakuliah Asal
A10: NO | B10: KODE | C10: MATA KULIAH | D10: SKS | E10: SKS Diakui | F10: Nilai | G10: KODE | H10: MATA KULIAH | I10: SKS | J10: Nilai
A11: SEMESTER 1
A12: 1 | B12: SI211103 | C12: Pendidikan Pancasila | D12: 2 | E12: =IF(AND($G12<>"",$H12<>"",$I12<>"",$J12<>""),$D12,"") -> 2 | F12: =IF(AND($G12<>"",$H12<>"",$I12<>"",$J12<>""),_xlfn.IFNA(VLOOKUP(UPPER(J12),'Konversi Nilai'!$B$3:$C$28,2,FALSE),""),"") -> B | G12: - | H12: Pancasila | I12: 2 | J12: B
A13: 2 | B13: SI211501 | C13: Pendidikan Bahasa Indonesia | D13: 2 | E13: =IF(AND($G13<>"",$H13<>"",$I13<>"",$J13<>""),$D13,"") -> 2 | F13: =IF(AND($G13<>"",$H13<>"",$I13<>"",$J13<>""),_xlfn.IFNA(VLOOKUP(UPPER(J13),'Konversi Nilai'!$B$3:$C$28,2,FALSE),""),"") -> C | G13: - | H13: Bahasa Indonesia | I13: 2 | J13: C
A14: 3 | B14: SI213103 | C14: Dasar Infrastruktur Teknologi | D14: 2 | E14: =IF(AND($G14<>"",$H14<>"",$I14<>"",$J14<>""),$D14,"") -> 2 | F14: =IF(AND($G14<>"",$H14<>"",$I14<>"",$J14<>""),_xlfn.IFNA(VLOOKUP(UPPER(J14),'Konversi Nilai'!$B$3:$C$28,2,FALSE),""),"") -> B | G14: - | H14: Piranti Masukan dan Keluaran | I14: 3 | J14: B
A15: 4 | B15: SI213108 | C15: Konsep dan Aplikasi Sistem Informasi | D15: 2 | E15: =IF(AND($G15<>"",$H15<>"",$I15<>"",$J15<>""),$D15,"") -> 2 | F15: =IF(AND($G15<>"",$H15<>"",$I15<>"",$J15<>""),_xlfn.IFNA(VLOOKUP(UPPER(J15),'Konversi Nilai'!$B$3:$C$28,2,FALSE),""),"") -> B | G15: - | H15: Pengenalan Komputer | I15: 3 | J15: B
A16: 5 | B16: SI213114 | C16: Matematika Diskrit | D16: 4 | E16: =IF(AND($G16<>"",$H16<>"",$I16<>"",$J16<>""),$D16,"") -> 4 | F16: =IF(AND($G16<>"",$H16<>"",$I16<>"",$J16<>""),_xlfn.IFNA(VLOOKUP(UPPER(J16),'Konversi Nilai'!$B$3:$C$28,2,FALSE),""),"") -> B | G16: - | H16: Matematika Diskrit | I16: 3 | J16: B
A17: 6 | B17: SI213117 | C17: Sistem Operasi | D17: 2 | E17: =IF(AND($G17<>"",$H17<>"",$I17<>"",$J17<>""),$D17,"") -> 2 | F17: =IF(AND($G17<>"",$H17<>"",$I17<>"",$J17<>""),_xlfn.IFNA(VLOOKUP(UPPER(J17),'Konversi Nilai'!$B$3:$C$28,2,FALSE),""),"") -> B | G17: - | H17: Sistem Operasi | I17: 3 | J17: B
A18: 7 | B18: SI213201 | C18: Prak. Algoritma dan Struktur Data | D18: 1 | E18: =IF(AND($G18<>"",$H18<>"",$I18<>"",$J18<>""),$D18,"") -> 1 | F18: =IF(AND($G18<>"",$H18<>"",$I18<>"",$J18<>""),_xlfn.IFNA(VLOOKUP(UPPER(J18),'Konversi Nilai'!$B$3:$C$28,2,FALSE),""),"") -> B | G18: - | H18: Bahasa Pemrograman Tingkat Tinggi I | I18: 3 | J18: B
A19: 8 | B19: SI213501 | C19: Algoritma dan Struktur Data | D19: 4 | E19: =IF(AND($G19<>"",$H19<>"",$I19<>"",$J19<>""),$D19,"") -> 4 | F19: =IF(AND($G19<>"",$H19<>"",$I19<>"",$J19<>""),_xlfn.IFNA(VLOOKUP(UPPER(J19),'Konversi Nilai'!$B$3:$C$28,2,FALSE),""),"") -> C | G19: - | H19: Struktur Data | I19: 3 | J19: C
A20: Total SKS | D20: =SUM(D12:D19) -> 19 | E20: =SUM(E12:E19) -> 19 | F20: =IF(I20<>"",J20,"") -> 0 | I20: =SUM(I12:I19) -> 22
A21: SEMESTER 2
A22: 9 | B22: SI213503 | C22: Basis Data | D22: 2 | E22: =IF(AND($G22<>"",$H22<>"",$I22<>"",$J22<>""),$D22,"") -> 2 | F22: =IF(AND($G22<>"",$H22<>"",$I22<>"",$J22<>""),_xlfn.IFNA(VLOOKUP(UPPER(J22),'Konversi Nilai'!$B$3:$C$28,2,FALSE),""),"") -> C | G22: - | H22: Pengantar Database | I22: 3 | J22: C
A23: 10 | B23: SI213504 | C23: E-Business | D23: 4 | E23: =IF(AND($G23<>"",$H23<>"",$I23<>"",$J23<>""),$D23,"") -> 4 | F23: =IF(AND($G23<>"",$H23<>"",$I23<>"",$J23<>""),_xlfn.IFNA(VLOOKUP(UPPER(J23),'Konversi Nilai'!$B$3:$C$28,2,FALSE),""),"") -> C | G23: - | H23: Algoritma Pemrograman I | I23: 3 | J23: C
A24: 11 | B24: SI213505 | C24: Jaringan Komputer | D24: 2 | E24: =IF(AND($G24<>"",$H24<>"",$I24<>"",$J24<>""),$D24,"") -> 2 | F24: =IF(AND($G24<>"",$H24<>"",$I24<>"",$J24<>""),_xlfn.IFNA(VLOOKUP(UPPER(J24),'Konversi Nilai'!$B$3:$C$28,2,FALSE),""),"") -> B | G24: - | H24: Jaringan Informasi Lokal | I24: 3 | J24: B
A25: 12 | B25: SI213202 | C25: Prak. Basis Data | D25: 1 | E25: =IF(AND($G25<>"",$H25<>"",$I25<>"",$J25<>""),$D25,"") -> 1 | F25: =IF(AND($G25<>"",$H25<>"",$I25<>"",$J25<>""),_xlfn.IFNA(VLOOKUP(UPPER(J25),'Konversi Nilai'!$B$3:$C$28,2,FALSE),""),"") -> C | G25: - | H25: Algoritma Pemrograman II | I25: 3 | J25: C
A26: 13 | B26: SI213203 | C26: Prak. Jaringan Komputer | D26: 1 | E26: =IF(AND($G26<>"",$H26<>"",$I26<>"",$J26<>""),$D26,"") -> 1 | F26: =IF(AND($G26<>"",$H26<>"",$I26<>"",$J26<>""),_xlfn.IFNA(VLOOKUP(UPPER(J26),'Konversi Nilai'!$B$3:$C$28,2,FALSE),""),"") -> B | G26: - | H26: Arsitektur Komputer II | I26: 3 | J26: B
A27: 14 | B27: SI211101 | C27: Pendidikan Agama | D27: 2 | E27: =IF(AND($G27<>"",$H27<>"",$I27<>"",$J27<>""),$D27,"") -> 2 | F27: =IF(AND($G27<>"",$H27<>"",$I27<>"",$J27<>""),_xlfn.IFNA(VLOOKUP(UPPER(J27),'Konversi Nilai'!$B$3:$C$28,2,FALSE),""),"") -> B | G27: - | H27: Agama | I27: 2 | J27: B
A28: 15 | B28: SI211102 | C28: Pendidikan Kewarganegaraan | D28: 2 | E28: =IF(AND($G28<>"",$H28<>"",$I28<>"",$J28<>""),$D28,"") -> 2 | F28: =IF(AND($G28<>"",$H28<>"",$I28<>"",$J28<>""),_xlfn.IFNA(VLOOKUP(UPPER(J28),'Konversi Nilai'!$B$3:$C$28,2,FALSE),""),"") -> B | G28: - | H28: Kewiraan | I28: 2 | J28: B
A29: 16 | B29: SI212503 | C29: Pendidikan Bahasa Asing I | D29: 4 | E29: =IF(AND($G29<>"",$H29<>"",$I29<>"",$J29<>""),$D29,"") -> 4 | F29: =IF(AND($G29<>"",$H29<>"",$I29<>"",$J29<>""),_xlfn.IFNA(VLOOKUP(UPPER(J29),'Konversi Nilai'!$B$3:$C$28,2,FALSE),""),"") -> A | G29: - | H29: Bahasa Inggris | I29: 2 | J29: A
A30: Total SKS | D30: =SUM(D22:D29) -> 18 | E30: =SUM(E22:E29) -> 18 | F30: =IF(I30<>"",J30,"") -> 0 | I30: =SUM(I22:I29) -> 21
A31: SEMESTER 3
A32: 17 | B32: SI212504 | C32: Pendidikan Bahasa Asing II | D32: 4 | E32: =IF(AND($G32<>"",$H32<>"",$I32<>"",$J32<>""),$D32,"") | F32: =IF(AND($G32<>"",$H32<>"",$I32<>"",$J32<>""),_xlfn.IFNA(VLOOKUP(UPPER(J32),'Konversi Nilai'!$B$3:$C$28,2,FALSE),""),"")
A33: 18 | B33: SI213102 | C33: Cloud Computing | D33: 2 | E33: =IF(AND($G33<>"",$H33<>"",$I33<>"",$J33<>""),$D33,"") -> 2 | F33: =IF(AND($G33<>"",$H33<>"",$I33<>"",$J33<>""),_xlfn.IFNA(VLOOKUP(UPPER(J33),'Konversi Nilai'!$B$3:$C$28,2,FALSE),""),"") -> B | G33: - | H33: Pengantar Sistem Tersebar | I33: 3 | J33: B
A34: 19 | B34: SI213118 | C34: Statistik | D34: 2 | E34: =IF(AND($G34<>"",$H34<>"",$I34<>"",$J34<>""),$D34,"") -> 2 | F34: =IF(AND($G34<>"",$H34<>"",$I34<>"",$J34<>""),_xlfn.IFNA(VLOOKUP(UPPER(J34),'Konversi Nilai'!$B$3:$C$28,2,FALSE),""),"") -> C | G34: - | H34: Statistik | I34: 3 | J34: C
A35: 20 | B35: SI213110 | C35: Manajemen Bisnis | D35: 2 | E35: =IF(AND($G35<>"",$H35<>"",$I35<>"",$J35<>""),$D35,"") -> 2 | F35: =IF(AND($G35<>"",$H35<>"",$I35<>"",$J35<>""),_xlfn.IFNA(VLOOKUP(UPPER(J35),'Konversi Nilai'!$B$3:$C$28,2,FALSE),""),"") -> C | G35: - | H35: Manajemen | I35: 3 | J35: C
A36: 21 | B36: SI213506 | C36: Project Management | D36: 4 | E36: =IF(AND($G36<>"",$H36<>"",$I36<>"",$J36<>""),$D36,"") | F36: =IF(AND($G36<>"",$H36<>"",$I36<>"",$J36<>""),_xlfn.IFNA(VLOOKUP(UPPER(J36),'Konversi Nilai'!$B$3:$C$28,2,FALSE),""),"")
A37: 22 | B37: SI213302 | C37: Pemrograman Web | D37: 4 | E37: =IF(AND($G37<>"",$H37<>"",$I37<>"",$J37<>""),$D37,"") -> 4 | F37: =IF(AND($G37<>"",$H37<>"",$I37<>"",$J37<>""),_xlfn.IFNA(VLOOKUP(UPPER(J37),'Konversi Nilai'!$B$3:$C$28,2,FALSE),""),"") -> B | G37: - | H37: Pemrograman Sistem | I37: 3 | J37: B
A38: 23 | B38: SI213116 | C38: Rekayasa Perangkat Lunak | D38: 4 | E38: =IF(AND($G38<>"",$H38<>"",$I38<>"",$J38<>""),$D38,"") -> 4 | F38: =IF(AND($G38<>"",$H38<>"",$I38<>"",$J38<>""),_xlfn.IFNA(VLOOKUP(UPPER(J38),'Konversi Nilai'!$B$3:$C$28,2,FALSE),""),"") -> C | G38: - | H38: Rekayasa Perangkat Lunak | I38: 3 | J38: C
A39: Total SKS | D39: =SUM(D32:D38) -> 22 | E39: =SUM(E32:E38) -> 14 | I39: =SUM(I32:I38) -> 15
A40: SEMESTER 4
A41: 24 | B41: SI213502 | C41: Analisis dan Perancangan Sistem | D41: 4 | E41: =IF(AND($G41<>"",$H41<>"",$I41<>"",$J41<>""),$D41,"") | F41: =IF(AND($G41<>"",$H41<>"",$I41<>"",$J41<>""),_xlfn.IFNA(VLOOKUP(UPPER(J41),'Konversi Nilai'!$B$3:$C$28,2,FALSE),""),"")
A42: 25 | B42: SI213509 | C42: User Experience | D42: 2 | E42: =IF(AND($G42<>"",$H42<>"",$I42<>"",$J42<>""),$D42,"") -> 2 | F42: =IF(AND($G42<>"",$H42<>"",$I42<>"",$J42<>""),_xlfn.IFNA(VLOOKUP(UPPER(J42),'Konversi Nilai'!$B$3:$C$28,2,FALSE),""),"") -> B | G42: - | H42: Komputer dan Masyarakat | I42: 3 | J42: B
...

Sheet Konversi Nilai
B2: Nilai Asal | C2: Nilai Diakui
B3: A | C3: A
B4: AB | C4: AB
B5: B | C5: B
B6: BC | C6: BC
B7: C | C7: C
B8: A- | C8: AB
B9: B+ | C9: AB
B10: B- | C10: BC
B11: C+ | C11: BC
