Workbook

Sheet Proses
A1: Hasil Transfer Nilai Sementara
A2: Program Studi Sistem Informasi ITB STIKOM Bali
A4: Nama Calon Mhs | C4: : I Made Oka Mahendra | G4: Prodi | H4: :Sistem Informasi
A5: Asal PT/Univ. | C5: : ITB STIKOM Bali | G5: Jenjang | H5: :ReNIM
A6: Fakultas | C6: : - | G6: Tgl. Proses | H6: : 6 Juli 2021
A7: Total SKS ditransfer | C7: =": "&D129&" SKS" -> : 40 SKS
A9: Matakuliah ITB STIKOM Bali | G9: Matakuliah Asal
A10: NO | B10: KODE | C10: MATA KULIAH | D10: SKS | E10: SKS Diakui | F10: Nilai | G10: KODE | H10: MATA KULIAH | I10: SKS | J10: Nilai
A11: SEMESTER 1
A12: 1 | B12: SI9105 | C12: Bahasa Inggris I | D12: 2 | E12: =IF(AND($G12<>"",$H12<>"",$I12<>"",$J12<>""),$D12,"") -> 2 | F12: =IF(AND($G12<>"",$H12<>"",$I12<>"",$J12<>""),$J12,"") -> AB | G12: SI9105 | H12: Bahasa Inggris I | I12: 2 | J12: AB
A13: 2 | B13: SI9208 | C13: Seni dan Budaya | D13: 2 | E13: =IF(AND($G13<>"",$H13<>"",$I13<>"",$J13<>""),$D13,"") -> 2 | F13: =IF(AND($G13<>"",$H13<>"",$I13<>"",$J13<>""),$J13,"") -> A | G13: SI9208 | H13: Seni Budaya | I13: 2 | J13: A
A14: 3 | B14: SI0201 | C14: Matematika Diskrit | D14: 4 | E14: =IF(AND($G14<>"",$H14<>"",$I14<>"",$J14<>""),$D14,"") -> 4 | F14: =IF(AND($G14<>"",$H14<>"",$I14<>"",$J14<>""),$J14,"") -> AB | G14: SI0201 | H14: Matematika Diskrit | I14: 4 | J14: AB
A15: 4 | B15: SI0202 | C15: Algoritma dan Pemrograman | D15: 2 | E15: =IF(AND($G15<>"",$H15<>"",$I15<>"",$J15<>""),$D15,"") -> 2 | F15: =IF(AND($G15<>"",$H15<>"",$I15<>"",$J15<>""),$J15,"") -> AB | G15: SI0202 | H15: Algoritma dan Pemrograman | I15: 2 | J15: AB
A16: 5 | B16: SI0304 | C16: Praktikum Algoritma dan Pemrograman | D16: 1 | E16: =IF(AND($G16<>"",$H16<>"",$I16<>"",$J16<>""),$D16,"") -> 1 | F16: =IF(AND($G16<>"",$H16<>"",$I16<>"",$J16<>""),$J16,"") -> AB | G16: SI0304 | H16: Praktikum Algoritma dan Pemrograman | I16: 1 | J16: AB
A17: 6 | B17: SI9203 | C17: Pengantar Teknologi Informasi | D17: 2 | E17: =IF(AND($G17<>"",$H17<>"",$I17<>"",$J17<>""),$D17,"") -> 2 | F17: =IF(AND($G17<>"",$H17<>"",$I17<>"",$J17<>""),$J17,"") -> AB | G17: SI9203 | H17: Pengantar Teknologi Informasi | I17: 2 | J17: AB
A18: 7 | B18: SI9301 | C18: Praktikum Pengantar Teknologi Informasi | D18: 1 | E18: =IF(AND($G18<>"",$H18<>"",$I18<>"",$J18<>""),$D18,"") -> 1 | F18: =IF(AND($G18<>"",$H18<>"",$I18<>"",$J18<>""),$J18,"") -> B | G18: SI9301 | H18: Praktikum Pengantar Teknologi Informasi | I18: 1 | J18: B
A19: 8 | B19: SI0102 | C19: Pancasila | D19: 2 | E19: =IF(AND($G19<>"",$H19<>"",$I19<>"",$J19<>""),$D19,"") -> 2 | F19: =IF(AND($G19<>"",$H19<>"",$I19<>"",$J19<>""),$J19,"") -> A | G19: SI0102 | H19: Pancasila | I19: 2 | J19: A
A20: 9 | B20: SI0221 | C20: Konsep dan Aplikasi Sistem Informasi | D20: 2 | E20: =IF(AND($G20<>"",$H20<>"",$I20<>"",$J20<>""),$D20,"") | F20: =IF(AND($G20<>"",$H20<>"",$I20<>"",$J20<>""),$J20,"")
A21: Total SKS | D21: =SUM(D12:D20) -> 18 | E21: =SUM(E12:E20) -> 16 | F21: =IF(I21<>"",J21,"")
A22: SEMESTER 2
A23: 1 | B23: SI0204 | C23: Komunikasi Data | D23: 4 | E23: =IF(AND($G23<>"",$H23<>"",$I23<>"",$J23<>""),$D23,"") -> 4 | F23: =IF(AND($G23<>"",$H23<>"",$I23<>"",$J23<>""),$J23,"") -> C | G23: SI0204 | H23: Komunikasi Data | I23: 4 | J23: C
A24: 2 | B24: SI0205 | C24: Basis Data | D24: 2 | E24: =IF(AND($G24<>"",$H24<>"",$I24<>"",$J24<>""),$D24,"") -> 2 | F24: =IF(AND($G24<>"",$H24<>"",$I24<>"",$J24<>""),$J24,"") -> B | G24: SI0205 | H24: Basis Data | I24: 2 | J24: B
A25: 3 | B25: SI0302 | C25: Praktikum Basis data | D25: 1 | E25: =IF(AND($G25<>"",$H25<>"",$I25<>"",$J25<>""),$D25,"") | F25: =IF(AND($G25<>"",$H25<>"",$I25<>"",$J25<>""),$J25,"")
A26: 4 | B26: SI0206 | C26: Struktur Data | D26: 2 | E26: =IF(AND($G26<>"",$H26<>"",$I26<>"",$J26<>""),$D26,"") -> 2 | F26: =IF(AND($G26<>"",$H26<>"",$I26<>"",$J26<>""),$J26,"") -> A | G26: SI0206 | H26: Struktur Data | I26: 2 | J26: A
A27: 5 | B27: SI0303 | C27: Praktikum Struktur Data | D27: 1 | E27: =IF(AND($G27<>"",$H27<>"",$I27<>"",$J27<>""),$D27,"") -> 1 | F27: =IF(AND($G27<>"",$H27<>"",$I27<>"",$J27<>""),$J27,"") -> C | G27: SI0303 | H27: Praktikum Struktur Data | I27: 1 | J27: C
A28: 6 | B28: SI9207 | C28: Organisasi Komputer | D28: 2 | E28: =IF(AND($G28<>"",$H28<>"",$I28<>"",$J28<>""),$D28,"") -> 2 | F28: =IF(AND($G28<>"",$H28<>"",$I28<>"",$J28<>""),$J28,"") -> C | G28: SI9207 | H28: Organisasi Komputer | I28: 2 | J28: C
A29: 7 | B29: SI9106 | C29: Bahasa Inggris II | D29: 2 | E29: =IF(AND($G29<>"",$H29<>"",$I29<>"",$J29<>""),$D29,"") | F29: =IF(AND($G29<>"",$H29<>"",$I29<>"",$J29<>""),$J29,"")
A30: 8 | B30: SI0103 | C30: Kewarganegaraan | D30: 2 | E30: =IF(AND($G30<>"",$H30<>"",$I30<>"",$J30<>""),$D30,"") | F30: =IF(AND($G30<>"",$H30<>"",$I30<>"",$J30<>""),$J30,"")
A31: 9 | B31: SI0101 | C31: Pendidikan Agama | D31: 2 | E31: =IF(AND($G31<>"",$H31<>"",$I31<>"",$J31<>""),$D31,"") | F31: =IF(AND($G31<>"",$H31<>"",$I31<>"",$J31<>""),$J31,"")
A32: Total SKS | D32: =SUM(D23:D31) -> 18 | E32: =SUM(E23:E31) -> 11 | F32: =IF(I32<>"",J32,"")
A33: SEMESTER 3
A34: 1 | B34: SI0209 | C34: Jaringan Komputer | D34: 2 | E34: =IF(AND($G34<>"",$H34<>"",$I34<>"",$J34<>""),$D34,"") -> 2 | F34: =IF(AND($G34<>"",$H34<>"",$I34<>"",$J34<>""),$J34,"") -> BC | G34: SI0209 | H34: Jaringan Komputer | I34: 2 | J34: BC
A35: 2 | B35: SI0305 | C35: Praktikum Jaringan Komputer | D35: 1 | E35: =IF(AND($G35<>"",$H35<>"",$I35<>"",$J35<>""),$D35,"") -> 1 | F35: =IF(AND($G35<>"",$H35<>"",$I35<>"",$J35<>""),$J35,"") -> AB | G35: SI0305 | H35: Praktikum Jaringan Komputer | I35: 1 | J35: AB
A36: 3 | B36: SI0306 | C36: Perancangan Web | D36: 4 | E36: =IF(AND($G36<>"",$H36<>"",$I36<>"",$J36<>""),$D36,"") -> 4 | F36: =IF(AND($G36<>"",$H36<>"",$I36<>"",$J36<>""),$J36,"") -> BC | G36: SI0306 | H36: Perancangan Web | I36: 4 | J36: BC
A37: 4 | B37: SI0211 | C37: Analisis dan Perancangan Sistem | D37: 4 | E37: =IF(AND($G37<>"",$H37<>"",$I37<>"",$J37<>""),$D37,"") | F37: =IF(AND($G37<>"",$H37<>"",$I37<>"",$J37<>""),$J37,"")
A38: 5 | B38: SI0307 | C38: Pemrograman Berorientasi Obyek | D38: 4 | E38: =IF(AND($G38<>"",$H38<>"",$I38<>"",$J38<>""),$D38,"") | F38: =IF(AND($G38<>"",$H38<>"",$I38<>"",$J38<>""),$J38,"")
A39: 6 | B39: SI0213 | C39: Sistem Operasi | D39: 2 | E39: =IF(AND($G39<>"",$H39<>"",$I39<>"",$J39<>""),$D39,"") | F39: =IF(AND($G39<>"",$H39<>"",$I39<>"",$J39<>""),$J39,"")
A40: 7 | B40: SI0217 | C40: Kalkulus | D40: 2 | E40: =IF(AND($G40<>"",$H40<>"",$I40<>"",$J40<>""),$D40,"") | F40: =IF(AND($G40<>"",$H40<>"",$I40<>"",$J40<>""),$J40,"")
A41: Total SKS | D41: =SUM(D34:D40) -> 19 | E41: =SUM(E34:E40) -> 7
A42: SEMESTER 4
...

Sheet ES
A1: Hasil Transfer Nilai Sementara
A2: Program Studi Sistem Informasi ITB STIKOM Bali
A4: Nama Calon Mhs | C4: =Proses!C4 -> : I Made Oka Mahendra | F4: Prodi | H4: =Proses!H4 -> :Sistem Informasi
A5: Asal PT/Univ. | C5: =Proses!C5 -> : ITB STIKOM Bali | F5: Jenjang | H5: =Proses!H5 -> :ReNIM
A6: Fakultas | C6: =Proses!C6 -> : - | F6: Tgl. Proses | H6: =Proses!H6 -> : 6 Juli 2021
A7: ="Total SKS yang ditransfer : "&D81&" SKS" -> Total SKS yang ditransfer : 38 SKS
A9: Matakuliah ITB STIKOM Bali | G9: Matakuliah Asal
A10: NO | B10: KODE | C10: MATA KULIAH | D10: SKS | E10: SKS Diakui | F10: Nilai | G10: KODE | H10: MATA KULIAH | I10: SKS | J10: Nilai
A11: SEMESTER 1
A12: 1 | B12: SI9105 | C12: Bahasa Inggris I | D12: 2 | E12: =IF(AND($G12<>"",$H12<>"",$I12<>"",$J12<>""),$D12,"") -> 2 | F12: =IF(AND($G12<>"",$H12<>"",$I12<>"",$J12<>""),$J12,"") -> AB | G12: =IF(AND(Proses!$G12<>"",Proses!$H12<>"",Proses!$I12<>"",Proses!$J12<>""),Proses!G12,"") -> SI9105 | H12: =IF(AND(Proses!$G12<>"",Proses!$H12<>"",Proses!$I12<>"",Proses!$J12<>""),Proses!H12,"") -> Bahasa Inggris I | I12: =IF(AND(Proses!$G12<>"",Proses!$H12<>"",Proses!$I12<>"",Proses!$J12<>""),Proses!I12,"") -> 2 | J12: =IF(AND(Proses!$G12<>"",Proses!$H12<>"",Proses!$I12<>"",Proses!$J12<>""),Proses!J12,"") -> AB
A13: 2 | B13: SI9208 | C13: Seni dan Budaya | D13: 2 | E13: =IF(AND($G13<>"",$H13<>"",$I13<>"",$J13<>""),$D13,"") -> 2 | F13: =IF(AND($G13<>"",$H13<>"",$I13<>"",$J13<>""),$J13,"") -> A | G13: =IF(AND(Proses!$G13<>"",Proses!$H13<>"",Proses!$I13<>"",Proses!$J13<>""),Proses!G13,"") -> SI9208 | H13: =IF(AND(Proses!$G13<>"",Proses!$H13<>"",Proses!$I13<>"",Proses!$J13<>""),Proses!H13,"") -> Seni Budaya | I13: =IF(AND(Proses!$G13<>"",Proses!$H13<>"",Proses!$I13<>"",Proses!$J13<>""),Proses!I13,"") -> 2 | J13: =IF(AND(Proses!$G13<>"",Proses!$H13<>"",Proses!$I13<>"",Proses!$J13<>""),Proses!J13,"") -> A
A14: 3 | B14: SI0201 | C14: Matematika Diskrit | D14: 4 | E14: =IF(AND($G14<>"",$H14<>"",$I14<>"",$J14<>""),$D14,"") -> 4 | F14: =IF(AND($G14<>"",$H14<>"",$I14<>"",$J14<>""),$J14,"") -> AB | G14: =IF(AND(Proses!$G14<>"",Proses!$H14<>"",Proses!$I14<>"",Proses!$J14<>""),Proses!G14,"") -> SI0201 | H14: =IF(AND(Proses!$G14<>"",Proses!$H14<>"",Proses!$I14<>"",Proses!$J14<>""),Proses!H14,"") -> Matematika Diskrit | I14: =IF(AND(Proses!$G14<>"",Proses!$H14<>"",Proses!$I14<>"",Proses!$J14<>""),Proses!I14,"") -> 4 | J14: =IF(AND(Proses!$G14<>"",Proses!$H14<>"",Proses!$I14<>"",Proses!$J14<>""),Proses!J14,"") -> AB
A15: 4 | B15: SI0202 | C15: Algoritma dan Pemrograman | D15: 2 | E15: =IF(AND($G15<>"",$H15<>"",$I15<>"",$J15<>""),$D15,"") -> 2 | F15: =IF(AND($G15<>"",$H15<>"",$I15<>"",$J15<>""),$J15,"") -> AB | G15: =IF(AND(Proses!$G15<>"",Proses!$H15<>"",Proses!$I15<>"",Proses!$J15<>""),Proses!G15,"") -> SI0202 | H15: =IF(AND(Proses!$G15<>"",Proses!$H15<>"",Proses!$I15<>"",Proses!$J15<>""),Proses!H15,"") -> Algoritma dan Pemrograman | I15: =IF(AND(Proses!$G15<>"",Proses!$H15<>"",Proses!$I15<>"",Proses!$J15<>""),Proses!I15,"") -> 2 | J15: =IF(AND(Proses!$G15<>"",Proses!$H15<>"",Proses!$I15<>"",Proses!$J15<>""),Proses!J15,"") -> AB
A16: 5 | B16: SI0304 | C16: Praktikum Algoritma dan Pemrograman | D16: 1 | E16: =IF(AND($G16<>"",$H16<>"",$I16<>"",$J16<>""),$D16,"") -> 1 | F16: =IF(AND($G16<>"",$H16<>"",$I16<>"",$J16<>""),$J16,"") -> AB | G16: =IF(AND(Proses!$G16<>"",Proses!$H16<>"",Proses!$I16<>"",Proses!$J16<>""),Proses!G16,"") -> SI0304 | H16: =IF(AND(Proses!$G16<>"",Proses!$H16<>"",Proses!$I16<>"",Proses!$J16<>""),Proses!H16,"") -> Praktikum Algoritma dan Pemrograman | I16: =IF(AND(Proses!$G16<>"",Proses!$H16<>"",Proses!$I16<>"",Proses!$J16<>""),Proses!I16,"") -> 1 | J16: =IF(AND(Proses!$G16<>"",Proses!$H16<>"",Proses!$I16<>"",Proses!$J16<>""),Proses!J16,"") -> AB
A17: 6 | B17: SI9203 | C17: Pengantar Teknologi Informasi | D17: 2 | E17: =IF(AND($G17<>"",$H17<>"",$I17<>"",$J17<>""),$D17,"") -> 2 | F17: =IF(AND($G17<>"",$H17<>"",$I17<>"",$J17<>""),$J17,"") -> AB | G17: =IF(AND(Proses!$G17<>"",Proses!$H17<>"",Proses!$I17<>"",Proses!$J17<>""),Proses!G17,"") -> SI9203 | H17: =IF(AND(Proses!$G17<>"",Proses!$H17<>"",Proses!$I17<>"",Proses!$J17<>""),Proses!H17,"") -> Pengantar Teknologi Informasi | I17: =IF(AND(Proses!$G17<>"",Proses!$H17<>"",Proses!$I17<>"",Proses!$J17<>""),Proses!I17,"") -> 2 | J17: =IF(AND(Proses!$G17<>"",Proses!$H17<>"",Proses!$I17<>"",Proses!$J17<>""),Proses!J17,"") -> AB
A18: 7 | B18: SI9301 | C18: Praktikum Pengantar Teknologi Informasi | D18: 1 | E18: =IF(AND($G18<>"",$H18<>"",$I18<>"",$J18<>""),$D18,"") -> 1 | F18: =IF(AND($G18<>"",$H18<>"",$I18<>"",$J18<>""),$J18,"") -> B | G18: =IF(AND(Proses!$G18<>"",Proses!$H18<>"",Proses!$I18<>"",Proses!$J18<>""),Proses!G18,"") -> SI9301 | H18: =IF(AND(Proses!$G18<>"",Proses!$H18<>"",Proses!$I18<>"",Proses!$J18<>""),Proses!H18,"") -> Praktikum Pengantar Teknologi Informasi | I18: =IF(AND(Proses!$G18<>"",Proses!$H18<>"",Proses!$I18<>"",Proses!$J18<>""),Proses!I18,"") -> 1 | J18: =IF(AND(Proses!$G18<>"",Proses!$H18<>"",Proses!$I18<>"",Proses!$J18<>""),Proses!J18,"") -> B
A19: 8 | B19: SI0102 | C19: Pancasila | D19: 2 | E19: =IF(AND($G19<>"",$H19<>"",$I19<>"",$J19<>""),$D19,"") -> 2 | F19: =IF(AND($G19<>"",$H19<>"",$I19<>"",$J19<>""),$J19,"") -> A | G19: =IF(AND(Proses!$G19<>"",Proses!$H19<>"",Proses!$I19<>"",Proses!$J19<>""),Proses!G19,"") -> SI0102 | H19: =IF(AND(Proses!$G19<>"",Proses!$H19<>"",Proses!$I19<>"",Proses!$J19<>""),Proses!H19,"") -> Pancasila | I19: =IF(AND(Proses!$G19<>"",Proses!$H19<>"",Proses!$I19<>"",Proses!$J19<>""),Proses!I19,"") -> 2 | J19: =IF(AND(Proses!$G19<>"",Proses!$H19<>"",Proses!$I19<>"",Proses!$J19<>""),Proses!J19,"") -> A
A20: 9 | B20: SI0221 | C20: Konsep dan Aplikasi Sistem Informasi | D20: 2 | E20: =IF(AND($G20<>"",$H20<>"",$I20<>"",$J20<>""),$D20,"") | F20: =IF(AND($G20<>"",$H20<>"",$I20<>"",$J20<>""),$J20,"") | G20: =IF(AND(Proses!$G20<>"",Proses!$H20<>"",Proses!$I20<>"",Proses!$J20<>""),Proses!G20,"") | H20: =IF(AND(Proses!$G20<>"",Proses!$H20<>"",Proses!$I20<>"",Proses!$J20<>""),Proses!H20,"") | I20: =IF(AND(Proses!$G20<>"",Proses!$H20<>"",Proses!$I20<>"",Proses!$J20<>""),Proses!I20,"") | J20: =IF(AND(Proses!$G20<>"",Proses!$H20<>"",Proses!$I20<>"",Proses!$J20<>""),Proses!J20,"")
A21: Total SKS | D21: =SUM(D12:D20) -> 18 | E21: =IF(Proses!E21 <>"",Proses!E21,"") -> 16 | F21: =IF(Proses!F21 <>"",Proses!F21,"") | G21: =IF(Proses!G21 <>"",Proses!G21,"") | H21: =IF(Proses!H21 <>"",Proses!H21,"") | I21: =IF(Proses!I21 <>"",Proses!I21,"") | J21: =IF(Proses!J21 <>"",Proses!J21,"")
A22: SEMESTER 2 | E22: =IF(Proses!E22 <>"",Proses!E22,"") | F22: =IF(Proses!F22 <>"",Proses!F22,"") | G22: =IF(Proses!G22 <>"",Proses!G22,"") | H22: =IF(Proses!H22 <>"",Proses!H22,"") | I22: =IF(Proses!I22 <>"",Proses!I22,"") | J22: =IF(Proses!J22 <>"",Proses!J22,"")
A23: 1 | B23: SI0204 | C23: Komunikasi Data | D23: 4 | E23: =IF(AND($G23<>"",$H23<>"",$I23<>"",$J23<>""),$D23,"") -> 4 | F23: =IF(AND($G23<>"",$H23<>"",$I23<>"",$J23<>""),$J23,"") -> C | G23: =IF(AND(Proses!$G23<>"",Proses!$H23<>"",Proses!$I23<>"",Proses!$J23<>""),Proses!G23,"") -> SI0204 | H23: =IF(AND(Proses!$G23<>"",Proses!$H23<>"",Proses!$I23<>"",Proses!$J23<>""),Proses!H23,"") -> Komunikasi Data | I23: =IF(AND(Proses!$G23<>"",Proses!$H23<>"",Proses!$I23<>"",Proses!$J23<>""),Proses!I23,"") -> 4 | J23: =IF(AND(Proses!$G23<>"",Proses!$H23<>"",Proses!$I23<>"",Proses!$J23<>""),Proses!J23,"") -> C
A24: 2 | B24: SI0205 | C24: Basis Data | D24: 2 | E24: =IF(AND($G24<>"",$H24<>"",$I24<>"",$J24<>""),$D24,"") -> 2 | F24: =IF(AND($G24<>"",$H24<>"",$I24<>"",$J24<>""),$J24,"") -> B | G24: =IF(AND(Proses!$G24<>"",Proses!$H24<>"",Proses!$I24<>"",Proses!$J24<>""),Proses!G24,"") -> SI0205 | H24: =IF(AND(Proses!$G24<>"",Proses!$H24<>"",Proses!$I24<>"",Proses!$J24<>""),Proses!H24,"") -> Basis Data | I24: =IF(AND(Proses!$G24<>"",Proses!$H24<>"",Proses!$I24<>"",Proses!$J24<>""),Proses!I24,"") -> 2 | J24: =IF(AND(Proses!$G24<>"",Proses!$H24<>"",Proses!$I24<>"",Proses!$J24<>""),Proses!J24,"") -> B
A25: 3 | B25: SI0302 | C25: Praktikum Basis data | D25: 1 | E25: =IF(AND($G25<>"",$H25<>"",$I25<>"",$J25<>""),$D25,"") | F25: =IF(AND($G25<>"",$H25<>"",$I25<>"",$J25<>""),$J25,"") | G25: =IF(AND(Proses!$G25<>"",Proses!$H25<>"",Proses!$I25<>"",Proses!$J25<>""),Proses!G25,"") | H25: =IF(AND(Proses!$G25<>"",Proses!$H25<>"",Proses!$I25<>"",Proses!$J25<>""),Proses!H25,"") | I25: =IF(AND(Proses!$G25<>"",Proses!$H25<>"",Proses!$I25<>"",Proses!$J25<>""),Proses!I25,"") | J25: =IF(AND(Proses!$G25<>"",Proses!$H25<>"",Proses!$I25<>"",Proses!$J25<>""),Proses!J25,"")
A26: 4 | B26: SI0206 | C26: Struktur Data | D26: 2 | E26: =IF(AND($G26<>"",$H26<>"",$I26<>"",$J26<>""),$D26,"") -> 2 | F26: =IF(AND($G26<>"",$H26<>"",$I26<>"",$J26<>""),$J26,"") -> A | G26: =IF(AND(Proses!$G26<>"",Proses!$H26<>"",Proses!$I26<>"",Proses!$J26<>""),Proses!G26,"") -> SI0206 | H26: =IF(AND(Proses!$G26<>"",Proses!$H26<>"",Proses!$I26<>"",Proses!$J26<>""),Proses!H26,"") -> Struktur Data | I26: =IF(AND(Proses!$G26<>"",Proses!$H26<>"",Proses!$I26<>"",Proses!$J26<>""),Proses!I26,"") -> 2 | J26: =IF(AND(Proses!$G26<>"",Proses!$H26<>"",Proses!$I26<>"",Proses!$J26<>""),Proses!J26,"") -> A
A27: 5 | B27: SI0303 | C27: Praktikum Struktur Data | D27: 1 | E27: =IF(AND($G27<>"",$H27<>"",$I27<>"",$J27<>""),$D27,"") -> 1 | F27: =IF(AND($G27<>"",$H27<>"",$I27<>"",$J27<>""),$J27,"") -> C | G27: =IF(AND(Proses!$G27<>"",Proses!$H27<>"",Proses!$I27<>"",Proses!$J27<>""),Proses!G27,"") -> SI0303 | H27: =IF(AND(Proses!$G27<>"",Proses!$H27<>"",Proses!$I27<>"",Proses!$J27<>""),Proses!H27,"") -> Praktikum Struktur Data | I27: =IF(AND(Proses!$G27<>"",Proses!$H27<>"",Proses!$I27<>"",Proses!$J27<>""),Proses!I27,"") -> 1 | J27: =IF(AND(Proses!$G27<>"",Proses!$H27<>"",Proses!$I27<>"",Proses!$J27<>""),Proses!J27,"") -> C
A28: 6 | B28: SI9207 | C28: Organisasi Komputer | D28: 2 | E28: =IF(AND($G28<>"",$H28<>"",$I28<>"",$J28<>""),$D28,"") -> 2 | F28: =IF(AND($G28<>"",$H28<>"",$I28<>"",$J28<>""),$J28,"") -> C | G28: =IF(AND(Proses!$G28<>"",Proses!$H28<>"",Proses!$I28<>"",Proses!$J28<>""),Proses!G28,"") -> SI9207 | H28: =IF(AND(Proses!$G28<>"",Proses!$H28<>"",Proses!$I28<>"",Proses!$J28<>""),Proses!H28,"") -> Organisasi Komputer | I28: =IF(AND(Proses!$G28<>"",Proses!$H28<>"",Proses!$I28<>"",Proses!$J28<>""),Proses!I28,"") -> 2 | J28: =IF(AND(Proses!$G28<>"",Proses!$H28<>"",Proses!$I28<>"",Proses!$J28<>""),Proses!J28,"") -> C
A29: 7 | B29: SI9106 | C29: Bahasa Inggris II | D29: 2 | E29: =IF(AND($G29<>"",$H29<>"",$I29<>"",$J29<>""),$D29,"") | F29: =IF(AND($G29<>"",$H29<>"",$I29<>"",$J29<>""),$J29,"") | G29: =IF(AND(Proses!$G29<>"",Proses!$H29<>"",Proses!$I29<>"",Proses!$J29<>""),Proses!G29,"") | H29: =IF(AND(Proses!$G29<>"",Proses!$H29<>"",Proses!$I29<>"",Proses!$J29<>""),Proses!H29,"") | I29: =IF(AND(Proses!$G29<>"",Proses!$H29<>"",Proses!$I29<>"",Proses!$J29<>""),Proses!I29,"") | J29: =IF(AND(Proses!$G29<>"",Proses!$H29<>"",Proses!$I29<>"",Proses!$J29<>""),Proses!J29,"")
A30: 8 | B30: SI0103 | C30: Kewarganegaraan | D30: 2 | E30: =IF(AND($G30<>"",$H30<>"",$I30<>"",$J30<>""),$D30,"") | F30: =IF(AND($G30<>"",$H30<>"",$I30<>"",$J30<>""),$J30,"") | G30: =IF(AND(Proses!$G30<>"",Proses!$H30<>"",Proses!$I30<>"",Proses!$J30<>""),Proses!G30,"") | H30: =IF(AND(Proses!$G30<>"",Proses!$H30<>"",Proses!$I30<>"",Proses!$J30<>""),Proses!H30,"") | I30: =IF(AND(Proses!$G30<>"",Proses!$H30<>"",Proses!$I30<>"",Proses!$J30<>""),Proses!I30,"") | J30: =IF(AND(Proses!$G30<>"",Proses!$H30<>"",Proses!$I30<>"",Proses!$J30<>""),Proses!J30,"")
A31: 9 | B31: SI0101 | C31: Pendidikan Agama | D31: 2 | E31: =IF(AND($G31<>"",$H31<>"",$I31<>"",$J31<>""),$D31,"") | F31: =IF(AND($G31<>"",$H31<>"",$I31<>"",$J31<>""),$J31,"") | G31: =IF(AND(Proses!$G31<>"",Proses!$H31<>"",Proses!$I31<>"",Proses!$J31<>""),Proses!G31,"") | H31: =IF(AND(Proses!$G31<>"",Proses!$H31<>"",Proses!$I31<>"",Proses!$J31<>""),Proses!H31,"") | I31: =IF(AND(Proses!$G31<>"",Proses!$H31<>"",Proses!$I31<>"",Proses!$J31<>""),Proses!I31,"") | J31: =IF(AND(Proses!$G31<>"",Proses!$H31<>"",Proses!$I31<>"",Proses!$J31<>""),Proses!J31,"")
A32: Total SKS | D32: =SUM(D23:D31) -> 18 | E32: =IF(Proses!E32 <>"",Proses!E32,"") -> 11 | F32: =IF(Proses!F32 <>"",Proses!F32,"") | G32: =IF(Proses!G32 <>"",Proses!G32,"") | H32: =IF(Proses!H32 <>"",Proses!H32,"") | I32: =IF(Proses!I32 <>"",Proses!I32,"") | J32: =IF(Proses!J32 <>"",Proses!J32,"")
A33: SEMESTER 3 | E33: =IF(Proses!E33 <>"",Proses!E33,"") | F33: =IF(Proses!F33 <>"",Proses!F33,"") | G33: =IF(Proses!G33 <>"",Proses!G33,"") | H33: =IF(Proses!H33 <>"",Proses!H33,"") | I33: =IF(Proses!I33 <>"",Proses!I33,"") | J33: =IF(Proses!J33 <>"",Proses!J33,"")
A34: 1 | B34: SI0209 | C34: Jaringan Komputer | D34: 2 | E34: =IF(AND($G34<>"",$H34<>"",$I34<>"",$J34<>""),$D34,"") -> 2 | F34: =IF(AND($G34<>"",$H34<>"",$I34<>"",$J34<>""),$J34,"") -> BC | G34: =IF(AND(Proses!$G34<>"",Proses!$H34<>"",Proses!$I34<>"",Proses!$J34<>""),Proses!G34,"") -> SI0209 | H34: =IF(AND(Proses!$G34<>"",Proses!$H34<>"",Proses!$I34<>"",Proses!$J34<>""),Proses!H34,"") -> Jaringan Komputer | I34: =IF(AND(Proses!$G34<>"",Proses!$H34<>"",Proses!$I34<>"",Proses!$J34<>""),Proses!I34,"") -> 2 | J34: =IF(AND(Proses!$G34<>"",Proses!$H34<>"",Proses!$I34<>"",Proses!$J34<>""),Proses!J34,"") -> BC
A35: 2 | B35: SI0305 | C35: Praktikum Jaringan Komputer | D35: 1 | E35: =IF(AND($G35<>"",$H35<>"",$I35<>"",$J35<>""),$D35,"") -> 1 | F35: =IF(AND($G35<>"",$H35<>"",$I35<>"",$J35<>""),$J35,"") -> AB | G35: =IF(AND(Proses!$G35<>"",Proses!$H35<>"",Proses!$I35<>"",Proses!$J35<>""),Proses!G35,"") -> SI0305 | H35: =IF(AND(Proses!$G35<>"",Proses!$H35<>"",Proses!$I35<>"",Proses!$J35<>""),Proses!H35,"") -> Praktikum Jaringan Komputer | I35: =IF(AND(Proses!$G35<>"",Proses!$H35<>"",Proses!$I35<>"",Proses!$J35<>""),Proses!I35,"") -> 1 | J35: =IF(AND(Proses!$G35<>"",Proses!$H35<>"",Proses!$I35<>"",Proses!$J35<>""),Proses!J35,"") -> AB
A36: 3 | B36: SI0306 | C36: Perancangan Web | D36: 4 | E36: =IF(AND($G36<>"",$H36<>"",$I36<>"",$J36<>""),$D36,"") -> 4 | F36: =IF(AND($G36<>"",$H36<>"",$I36<>"",$J36<>""),$J36,"") -> BC | G36: =IF(AND(Proses!$G36<>"",Proses!$H36<>"",Proses!$I36<>"",Proses!$J36<>""),Proses!G36,"") -> SI0306 | H36: =IF(AND(Proses!$G36<>"",Proses!$H36<>"",Proses!$I36<>"",Proses!$J36<>""),Proses!H36,"") -> Perancangan Web | I36: =IF(AND(Proses!$G36<>"",Proses!$H36<>"",Proses!$I36<>"",Proses!$J36<>""),Proses!I36,"") -> 4 | J36: =IF(AND(Proses!$G36<>"",Proses!$H36<>"",Proses!$I36<>"",Proses!$J36<>""),Proses!J36,"") -> BC
A37: 4 | B37: SI0211 | C37: Analisis dan Perancangan Sistem | D37: 4 | E37: =IF(AND($G37<>"",$H37<>"",$I37<>"",$J37<>""),$D37,"") | F37: =IF(AND($G37<>"",$H37<>"",$I37<>"",$J37<>""),$J37,"") | G37: =IF(AND(Proses!$G37<>"",Proses!$H37<>"",Proses!$I37<>"",Proses!$J37<>""),Proses!G37,"") | H37: =IF(AND(Proses!$G37<>"",Proses!$H37<>"",Proses!$I37<>"",Proses!$J37<>""),Proses!H37,"") | I37: =IF(AND(Proses!$G37<>"",Proses!$H37<>"",Proses!$I37<>"",Proses!$J37<>""),Proses!I37,"") | J37: =IF(AND(Proses!$G37<>"",Proses!$H37<>"",Proses!$I37<>"",Proses!$J37<>""),Proses!J37,"")
A38: 5 | B38: SI0307 | C38: Pemrograman Berorientasi Obyek | D38: 4 | E38: =IF(AND($G38<>"",$H38<>"",$I38<>"",$J38<>""),$D38,"") | F38: =IF(AND($G38<>"",$H38<>"",$I38<>"",$J38<>""),$J38,"") | G38: =IF(AND(Proses!$G38<>"",Proses!$H38<>"",Proses!$I38<>"",Proses!$J38<>""),Proses!G38,"") | H38: =IF(AND(Proses!$G38<>"",Proses!$H38<>"",Proses!$I38<>"",Proses!$J38<>""),Proses!H38,"") | I38: =IF(AND(Proses!$G38<>"",Proses!$H38<>"",Proses!$I38<>"",Proses!$J38<>""),Proses!I38,"") | J38: =IF(AND(Proses!$G38<>"",Proses!$H38<>"",Proses!$I38<>"",Proses!$J38<>""),Proses!J38,"")
A39: 6 | B39: SI0213 | C39: Sistem Operasi | D39: 2 | E39: =IF(AND($G39<>"",$H39<>"",$I39<>"",$J39<>""),$D39,"") | F39: =IF(AND($G39<>"",$H39<>"",$I39<>"",$J39<>""),$J39,"") | G39: =IF(AND(Proses!$G39<>"",Proses!$H39<>"",Proses!$I39<>"",Proses!$J39<>""),Proses!G39,"") | H39: =IF(AND(Proses!$G39<>"",Proses!$H39<>"",Proses!$I39<>"",Proses!$J39<>""),Proses!H39,"") | I39: =IF(AND(Proses!$G39<>"",Proses!$H39<>"",Proses!$I39<>"",Proses!$J39<>""),Proses!I39,"") | J39: =IF(AND(Proses!$G39<>"",Proses!$H39<>"",Proses!$I39<>"",Proses!$J39<>""),Proses!J39,"")
A40: 7 | B40: SI0217 | C40: Kalkulus | D40: 2 | E40: =IF(AND($G40<>"",$H40<>"",$I40<>"",$J40<>""),$D40,"") | F40: =IF(AND($G40<>"",$H40<>"",$I40<>"",$J40<>""),$J40,"") | G40: =IF(AND(Proses!$G40<>"",Proses!$H40<>"",Proses!$I40<>"",Proses!$J40<>""),Proses!G40,"") | H40: =IF(AND(Proses!$G40<>"",Proses!$H40<>"",Proses!$I40<>"",Proses!$J40<>""),Proses!H40,"") | I40: =IF(AND(Proses!$G40<>"",Proses!$H40<>"",Proses!$I40<>"",Proses!$J40<>""),Proses!I40,"") | J40: =IF(AND(Proses!$G40<>"",Proses!$H40<>"",Proses!$I40<>"",Proses!$J40<>""),Proses!J40,"")
A41: Total SKS | D41: =SUM(D34:D40) -> 19 | E41: =IF(Proses!E41 <>"",Proses!E41,"") -> 7 | F41: =IF(Proses!F41 <>"",Proses!F41,"") | G41: =IF(Proses!G41 <>"",Proses!G41,"") | H41: =IF(Proses!H41 <>"",Proses!H41,"") | I41: =IF(Proses!I41 <>"",Proses!I41,"") | J41: =IF(Proses!J41 <>"",Proses!J41,"")
A42: SEMESTER 4 | E42: =IF(Proses!E42 <>"",Proses!E42,"") | F42: =IF(Proses!F42 <>"",Proses!F42,"") | G42: =IF(Proses!G42 <>"",Proses!G42,"") | H42: =IF(Proses!H42 <>"",Proses!H42,"") | I42: =IF(Proses!I42 <>"",Proses!I42,"") | J42: =IF(Proses!J42 <>"",Proses!J42,"")
...

Sheet GM
A1: Hasil Transfer Nilai Sementara
A2: Program Studi Sistem Informasi ITB STIKOM Bali
A4: Nama Calon Mhs | C4: =Proses!C4 -> : I Made Oka Mahendra | F4: Prodi | H4: =Proses!H4 -> :Sistem Informasi
A5: Asal PT/Univ. | C5: =Proses!C5 -> : ITB STIKOM Bali | F5: Jenjang | H5: =Proses!H5 -> :ReNIM
A6: Fakultas | C6: =Proses!C6 -> : - | F6: Tgl. Proses | H6: =Proses!H6 -> : 6 Juli 2021
A7: ="Total SKS yang ditransfer : "&D81&" SKS" -> Total SKS yang ditransfer : 40 SKS
A9: Matakuliah ITB STIKOM Bali | G9: Matakuliah Asal
A10: NO | B10: KODE | C10: MATA KULIAH | D10: SKS | E10: SKS Diakui | F10: Nilai | G10: KODE | H10: MATA KULIAH | I10: SKS | J10: Nilai
A11: SEMESTER 1
A12: 1 | B12: SI9105 | C12: Bahasa Inggris I | D12: 2 | E12: =IF(AND($G12<>"",$H12<>"",$I12<>"",$J12<>""),$D12,"") -> 2 | F12: =IF(AND($G12<>"",$H12<>"",$I12<>"",$J12<>""),$J12,"") -> AB | G12: =IF(AND(Proses!$G12<>"",Proses!$H12<>"",Proses!$I12<>"",Proses!$J12<>""),Proses!G12,"") -> SI9105 | H12: =IF(AND(Proses!$G12<>"",Proses!$H12<>"",Proses!$I12<>"",Proses!$J12<>""),Proses!H12,"") -> Bahasa Inggris I | I12: =IF(AND(Proses!$G12<>"",Proses!$H12<>"",Proses!$I12<>"",Proses!$J12<>""),Proses!I12,"") -> 2 | J12: =IF(AND(Proses!$G12<>"",Proses!$H12<>"",Proses!$I12<>"",Proses!$J12<>""),Proses!J12,"") -> AB
A13: 2 | B13: SI9208 | C13: Seni dan Budaya | D13: 2 | E13: =IF(AND($G13<>"",$H13<>"",$I13<>"",$J13<>""),$D13,"") -> 2 | F13: =IF(AND($G13<>"",$H13<>"",$I13<>"",$J13<>""),$J13,"") -> A | G13: =IF(AND(Proses!$G13<>"",Proses!$H13<>"",Proses!$I13<>"",Proses!$J13<>""),Proses!G13,"") -> SI9208 | H13: =IF(AND(Proses!$G13<>"",Proses!$H13<>"",Proses!$I13<>"",Proses!$J13<>""),Proses!H13,"") -> Seni Budaya | I13: =IF(AND(Proses!$G13<>"",Proses!$H13<>"",Proses!$I13<>"",Proses!$J13<>""),Proses!I13,"") -> 2 | J13: =IF(AND(Proses!$G13<>"",Proses!$H13<>"",Proses!$I13<>"",Proses!$J13<>""),Proses!J13,"") -> A
A14: 3 | B14: SI0201 | C14: Matematika Diskrit | D14: 4 | E14: =IF(AND($G14<>"",$H14<>"",$I14<>"",$J14<>""),$D14,"") -> 4 | F14: =IF(AND($G14<>"",$H14<>"",$I14<>"",$J14<>""),$J14,"") -> AB | G14: =IF(AND(Proses!$G14<>"",Proses!$H14<>"",Proses!$I14<>"",Proses!$J14<>""),Proses!G14,"") -> SI0201 | H14: =IF(AND(Proses!$G14<>"",Proses!$H14<>"",Proses!$I14<>"",Proses!$J14<>""),Proses!H14,"") -> Matematika Diskrit | I14: =IF(AND(Proses!$G14<>"",Proses!$H14<>"",Proses!$I14<>"",Proses!$J14<>""),Proses!I14,"") -> 4 | J14: =IF(AND(Proses!$G14<>"",Proses!$H14<>"",Proses!$I14<>"",Proses!$J14<>""),Proses!J14,"") -> AB
A15: 4 | B15: SI0202 | C15: Algoritma dan Pemrograman | D15: 2 | E15: =IF(AND($G15<>"",$H15<>"",$I15<>"",$J15<>""),$D15,"") -> 2 | F15: =IF(AND($G15<>"",$H15<>"",$I15<>"",$J15<>""),$J15,"") -> AB | G15: =IF(AND(Proses!$G15<>"",Proses!$H15<>"",Proses!$I15<>"",Proses!$J15<>""),Proses!G15,"") -> SI0202 | H15: =IF(AND(Proses!$G15<>"",Proses!$H15<>"",Proses!$I15<>"",Proses!$J15<>""),Proses!H15,"") -> Algoritma dan Pemrograman | I15: =IF(AND(Proses!$G15<>"",Proses!$H15<>"",Proses!$I15<>"",Proses!$J15<>""),Proses!I15,"") -> 2 | J15: =IF(AND(Proses!$G15<>"",Proses!$H15<>"",Proses!$I15<>"",Proses!$J15<>""),Proses!J15,"") -> AB
A16: 5 | B16: SI0304 | C16: Praktikum Algoritma dan Pemrograman | D16: 1 | E16: =IF(AND($G16<>"",$H16<>"",$I16<>"",$J16<>""),$D16,"") -> 1 | F16: =IF(AND($G16<>"",$H16<>"",$I16<>"",$J16<>""),$J16,"") -> AB | G16: =IF(AND(Proses!$G16<>"",Proses!$H16<>"",Proses!$I16<>"",Proses!$J16<>""),Proses!G16,"") -> SI0304 | H16: =IF(AND(Proses!$G16<>"",Proses!$H16<>"",Proses!$I16<>"",Proses!$J16<>""),Proses!H16,"") -> Praktikum Algoritma dan Pemrograman | I16: =IF(AND(Proses!$G16<>"",Proses!$H16<>"",Proses!$I16<>"",Proses!$J16<>""),Proses!I16,"") -> 1 | J16: =IF(AND(Proses!$G16<>"",Proses!$H16<>"",Proses!$I16<>"",Proses!$J16<>""),Proses!J16,"") -> AB
A17: 6 | B17: SI9203 | C17: Pengantar Teknologi Informasi | D17: 2 | E17: =IF(AND($G17<>"",$H17<>"",$I17<>"",$J17<>""),$D17,"") -> 2 | F17: =IF(AND($G17<>"",$H17<>"",$I17<>"",$J17<>""),$J17,"") -> AB | G17: =IF(AND(Proses!$G17<>"",Proses!$H17<>"",Proses!$I17<>"",Proses!$J17<>""),Proses!G17,"") -> SI9203 | H17: =IF(AND(Proses!$G17<>"",Proses!$H17<>"",Proses!$I17<>"",Proses!$J17<>""),Proses!H17,"") -> Pengantar Teknologi Informasi | I17: =IF(AND(Proses!$G17<>"",Proses!$H17<>"",Proses!$I17<>"",Proses!$J17<>""),Proses!I17,"") -> 2 | J17: =IF(AND(Proses!$G17<>"",Proses!$H17<>"",Proses!$I17<>"",Proses!$J17<>""),Proses!J17,"") -> AB
A18: 7 | B18: SI9301 | C18: Praktikum Pengantar Teknologi Informasi | D18: 1 | E18: =IF(AND($G18<>"",$H18<>"",$I18<>"",$J18<>""),$D18,"") -> 1 | F18: =IF(AND($G18<>"",$H18<>"",$I18<>"",$J18<>""),$J18,"") -> B | G18: =IF(AND(Proses!$G18<>"",Proses!$H18<>"",Proses!$I18<>"",Proses!$J18<>""),Proses!G18,"") -> SI9301 | H18: =IF(AND(Proses!$G18<>"",Proses!$H18<>"",Proses!$I18<>"",Proses!$J18<>""),Proses!H18,"") -> Praktikum Pengantar Teknologi Informasi | I18: =IF(AND(Proses!$G18<>"",Proses!$H18<>"",Proses!$I18<>"",Proses!$J18<>""),Proses!I18,"") -> 1 | J18: =IF(AND(Proses!$G18<>"",Proses!$H18<>"",Proses!$I18<>"",Proses!$J18<>""),Proses!J18,"") -> B
A19: 8 | B19: SI0102 | C19: Pancasila | D19: 2 | E19: =IF(AND($G19<>"",$H19<>"",$I19<>"",$J19<>""),$D19,"") -> 2 | F19: =IF(AND($G19<>"",$H19<>"",$I19<>"",$J19<>""),$J19,"") -> A | G19: =IF(AND(Proses!$G19<>"",Proses!$H19<>"",Proses!$I19<>"",Proses!$J19<>""),Proses!G19,"") -> SI0102 | H19: =IF(AND(Proses!$G19<>"",Proses!$H19<>"",Proses!$I19<>"",Proses!$J19<>""),Proses!H19,"") -> Pancasila | I19: =IF(AND(Proses!$G19<>"",Proses!$H19<>"",Proses!$I19<>"",Proses!$J19<>""),Proses!I19,"") -> 2 | J19: =IF(AND(Proses!$G19<>"",Proses!$H19<>"",Proses!$I19<>"",Proses!$J19<>""),Proses!J19,"") -> A
A20: 9 | B20: SI0221 | C20: Konsep dan Aplikasi Sistem Informasi | D20: 2 | E20: =IF(AND($G20<>"",$H20<>"",$I20<>"",$J20<>""),$D20,"") | F20: =IF(AND($G20<>"",$H20<>"",$I20<>"",$J20<>""),$J20,"") | G20: =IF(AND(Proses!$G20<>"",Proses!$H20<>"",Proses!$I20<>"",Proses!$J20<>""),Proses!G20,"") | H20: =IF(AND(Proses!$G20<>"",Proses!$H20<>"",Proses!$I20<>"",Proses!$J20<>""),Proses!H20,"") | I20: =IF(AND(Proses!$G20<>"",Proses!$H20<>"",Proses!$I20<>"",Proses!$J20<>""),Proses!I20,"") | J20: =IF(AND(Proses!$G20<>"",Proses!$H20<>"",Proses!$I20<>"",Proses!$J20<>""),Proses!J20,"")
A21: Total SKS | D21: =SUM(D12:D20) -> 18 | E21: =IF(Proses!E21 <>"",Proses!E21,"") -> 16 | F21: =IF(Proses!F21 <>"",Proses!F21,"") | G21: =IF(Proses!G21 <>"",Proses!G21,"") | H21: =IF(Proses!H21 <>"",Proses!H21,"") | I21: =IF(Proses!I21 <>"",Proses!I21,"") | J21: =IF(Proses!J21 <>"",Proses!J21,"")
A22: SEMESTER 2 | E22: =IF(Proses!E22 <>"",Proses!E22,"") | F22: =IF(Proses!F22 <>"",Proses!F22,"") | G22: =IF(Proses!G22 <>"",Proses!G22,"") | H22: =IF(Proses!H22 <>"",Proses!H22,"") | I22: =IF(Proses!I22 <>"",Proses!I22,"") | J22: =IF(Proses!J22 <>"",Proses!J22,"")
A23: 1 | B23: SI0204 | C23: Komunikasi Data | D23: 4 | E23: =IF(AND($G23<>"",$H23<>"",$I23<>"",$J23<>""),$D23,"") -> 4 | F23: =IF(AND($G23<>"",$H23<>"",$I23<>"",$J23<>""),$J23,"") -> C | G23: =IF(AND(Proses!$G23<>"",Proses!$H23<>"",Proses!$I23<>"",Proses!$J23<>""),Proses!G23,"") -> SI0204 | H23: =IF(AND(Proses!$G23<>"",Proses!$H23<>"",Proses!$I23<>"",Proses!$J23<>""),Proses!H23,"") -> Komunikasi Data | I23: =IF(AND(Proses!$G23<>"",Proses!$H23<>"",Proses!$I23<>"",Proses!$J23<>""),Proses!I23,"") -> 4 | J23: =IF(AND(Proses!$G23<>"",Proses!$H23<>"",Proses!$I23<>"",Proses!$J23<>""),Proses!J23,"") -> C
A24: 2 | B24: SI0205 | C24: Basis Data | D24: 2 | E24: =IF(AND($G24<>"",$H24<>"",$I24<>"",$J24<>""),$D24,"") -> 2 | F24: =IF(AND($G24<>"",$H24<>"",$I24<>"",$J24<>""),$J24,"") -> B | G24: =IF(AND(Proses!$G24<>"",Proses!$H24<>"",Proses!$I24<>"",Proses!$J24<>""),Proses!G24,"") -> SI0205 | H24: =IF(AND(Proses!$G24<>"",Proses!$H24<>"",Proses!$I24<>"",Proses!$J24<>""),Proses!H24,"") -> Basis Data | I24: =IF(AND(Proses!$G24<>"",Proses!$H24<>"",Proses!$I24<>"",Proses!$J24<>""),Proses!I24,"") -> 2 | J24: =IF(AND(Proses!$G24<>"",Proses!$H24<>"",Proses!$I24<>"",Proses!$J24<>""),Proses!J24,"") -> B
A25: 3 | B25: SI0302 | C25: Praktikum Basis data | D25: 1 | E25: =IF(AND($G25<>"",$H25<>"",$I25<>"",$J25<>""),$D25,"") | F25: =IF(AND($G25<>"",$H25<>"",$I25<>"",$J25<>""),$J25,"") | G25: =IF(AND(Proses!$G25<>"",Proses!$H25<>"",Proses!$I25<>"",Proses!$J25<>""),Proses!G25,"") | H25: =IF(AND(Proses!$G25<>"",Proses!$H25<>"",Proses!$I25<>"",Proses!$J25<>""),Proses!H25,"") | I25: =IF(AND(Proses!$G25<>"",Proses!$H25<>"",Proses!$I25<>"",Proses!$J25<>""),Proses!I25,"") | J25: =IF(AND(Proses!$G25<>"",Proses!$H25<>"",Proses!$I25<>"",Proses!$J25<>""),Proses!J25,"")
A26: 4 | B26: SI0206 | C26: Struktur Data | D26: 2 | E26: =IF(AND($G26<>"",$H26<>"",$I26<>"",$J26<>""),$D26,"") -> 2 | F26: =IF(AND($G26<>"",$H26<>"",$I26<>"",$J26<>""),$J26,"") -> A | G26: =IF(AND(Proses!$G26<>"",Proses!$H26<>"",Proses!$I26<>"",Proses!$J26<>""),Proses!G26,"") -> SI0206 | H26: =IF(AND(Proses!$G26<>"",Proses!$H26<>"",Proses!$I26<>"",Proses!$J26<>""),Proses!H26,"") -> Struktur Data | I26: =IF(AND(Proses!$G26<>"",Proses!$H26<>"",Proses!$I26<>"",Proses!$J26<>""),Proses!I26,"") -> 2 | J26: =IF(AND(Proses!$G26<>"",Proses!$H26<>"",Proses!$I26<>"",Proses!$J26<>""),Proses!J26,"") -> A
A27: 5 | B27: SI0303 | C27: Praktikum Struktur Data | D27: 1 | E27: =IF(AND($G27<>"",$H27<>"",$I27<>"",$J27<>""),$D27,"") -> 1 | F27: =IF(AND($G27<>"",$H27<>"",$I27<>"",$J27<>""),$J27,"") -> C | G27: =IF(AND(Proses!$G27<>"",Proses!$H27<>"",Proses!$I27<>"",Proses!$J27<>""),Proses!G27,"") -> SI0303 | H27: =IF(AND(Proses!$G27<>"",Proses!$H27<>"",Proses!$I27<>"",Proses!$J27<>""),Proses!H27,"") -> Praktikum Struktur Data | I27: =IF(AND(Proses!$G27<>"",Proses!$H27<>"",Proses!$I27<>"",Proses!$J27<>""),Proses!I27,"") -> 1 | J27: =IF(AND(Proses!$G27<>"",Proses!$H27<>"",Proses!$I27<>"",Proses!$J27<>""),Proses!J27,"") -> C
A28: 6 | B28: SI9207 | C28: Organisasi Komputer | D28: 2 | E28: =IF(AND($G28<>"",$H28<>"",$I28<>"",$J28<>""),$D28,"") -> 2 | F28: =IF(AND($G28<>"",$H28<>"",$I28<>"",$J28<>""),$J28,"") -> C | G28: =IF(AND(Proses!$G28<>"",Proses!$H28<>"",Proses!$I28<>"",Proses!$J28<>""),Proses!G28,"") -> SI9207 | H28: =IF(AND(Proses!$G28<>"",Proses!$H28<>"",Proses!$I28<>"",Proses!$J28<>""),Proses!H28,"") -> Organisasi Komputer | I28: =IF(AND(Proses!$G28<>"",Proses!$H28<>"",Proses!$I28<>"",Proses!$J28<>""),Proses!I28,"") -> 2 | J28: =IF(AND(Proses!$G28<>"",Proses!$H28<>"",Proses!$I28<>"",Proses!$J28<>""),Proses!J28,"") -> C
A29: 7 | B29: SI9106 | C29: Bahasa Inggris II | D29: 2 | E29: =IF(AND($G29<>"",$H29<>"",$I29<>"",$J29<>""),$D29,"") | F29: =IF(AND($G29<>"",$H29<>"",$I29<>"",$J29<>""),$J29,"") | G29: =IF(AND(Proses!$G29<>"",Proses!$H29<>"",Proses!$I29<>"",Proses!$J29<>""),Proses!G29,"") | H29: =IF(AND(Proses!$G29<>"",Proses!$H29<>"",Proses!$I29<>"",Proses!$J29<>""),Proses!H29,"") | I29: =IF(AND(Proses!$G29<>"",Proses!$H29<>"",Proses!$I29<>"",Proses!$J29<>""),Proses!I29,"") | J29: =IF(AND(Proses!$G29<>"",Proses!$H29<>"",Proses!$I29<>"",Proses!$J29<>""),Proses!J29,"")
A30: 8 | B30: SI0103 | C30: Kewarganegaraan | D30: 2 | E30: =IF(AND($G30<>"",$H30<>"",$I30<>"",$J30<>""),$D30,"") | F30: =IF(AND($G30<>"",$H30<>"",$I30<>"",$J30<>""),$J30,"") | G30: =IF(AND(Proses!$G30<>"",Proses!$H30<>"",Proses!$I30<>"",Proses!$J30<>""),Proses!G30,"") | H30: =IF(AND(Proses!$G30<>"",Proses!$H30<>"",Proses!$I30<>"",Proses!$J30<>""),Proses!H30,"") | I30: =IF(AND(Proses!$G30<>"",Proses!$H30<>"",Proses!$I30<>"",Proses!$J30<>""),Proses!I30,"") | J30: =IF(AND(Proses!$G30<>"",Proses!$H30<>"",Proses!$I30<>"",Proses!$J30<>""),Proses!J30,"")
A31: 9 | B31: SI0101 | C31: Pendidikan Agama | D31: 2 | E31: =IF(AND($G31<>"",$H31<>"",$I31<>"",$J31<>""),$D31,"") | F31: =IF(AND($G31<>"",$H31<>"",$I31<>"",$J31<>""),$J31,"") | G31: =IF(AND(Proses!$G31<>"",Proses!$H31<>"",Proses!$I31<>"",Proses!$J31<>""),Proses!G31,"") | H31: =IF(AND(Proses!$G31<>"",Proses!$H31<>"",Proses!$I31<>"",Proses!$J31<>""),Proses!H31,"") | I31: =IF(AND(Proses!$G31<>"",Proses!$H31<>"",Proses!$I31<>"",Proses!$J31<>""),Proses!I31,"") | J31: =IF(AND(Proses!$G31<>"",Proses!$H31<>"",Proses!$I31<>"",Proses!$J31<>""),Proses!J31,"")
A32: Total SKS | D32: =SUM(D23:D31) -> 18 | E32: =IF(Proses!E32 <>"",Proses!E32,"") -> 11 | F32: =IF(Proses!F32 <>"",Proses!F32,"") | G32: =IF(Proses!G32 <>"",Proses!G32,"") | H32: =IF(Proses!H32 <>"",Proses!H32,"") | I32: =IF(Proses!I32 <>"",Proses!I32,"") | J32: =IF(Proses!J32 <>"",Proses!J32,"")
A33: SEMESTER 3 | E33: =IF(Proses!E33 <>"",Proses!E33,"") | F33: =IF(Proses!F33 <>"",Proses!F33,"") | G33: =IF(Proses!G33 <>"",Proses!G33,"") | H33: =IF(Proses!H33 <>"",Proses!H33,"") | I33: =IF(Proses!I33 <>"",Proses!I33,"") | J33: =IF(Proses!J33 <>"",Proses!J33,"")
A34: 1 | B34: SI0209 | C34: Jaringan Komputer | D34: 2 | E34: =IF(AND($G34<>"",$H34<>"",$I34<>"",$J34<>""),$D34,"") -> 2 | F34: =IF(AND($G34<>"",$H34<>"",$I34<>"",$J34<>""),$J34,"") -> BC | G34: =IF(AND(Proses!$G34<>"",Proses!$H34<>"",Proses!$I34<>"",Proses!$J34<>""),Proses!G34,"") -> SI0209 | H34: =IF(AND(Proses!$G34<>"",Proses!$H34<>"",Proses!$I34<>"",Proses!$J34<>""),Proses!H34,"") -> Jaringan Komputer | I34: =IF(AND(Proses!$G34<>"",Proses!$H34<>"",Proses!$I34<>"",Proses!$J34<>""),Proses!I34,"") -> 2 | J34: =IF(AND(Proses!$G34<>"",Proses!$H34<>"",Proses!$I34<>"",Proses!$J34<>""),Proses!J34,"") -> BC
A35: 2 | B35: SI0305 | C35: Praktikum Jaringan Komputer | D35: 1 | E35: =IF(AND($G35<>"",$H35<>"",$I35<>"",$J35<>""),$D35,"") -> 1 | F35: =IF(AND($G35<>"",$H35<>"",$I35<>"",$J35<>""),$J35,"") -> AB | G35: =IF(AND(Proses!$G35<>"",Proses!$H35<>"",Proses!$I35<>"",Proses!$J35<>""),Proses!G35,"") -> SI0305 | H35: =IF(AND(Proses!$G35<>"",Proses!$H35<>"",Proses!$I35<>"",Proses!$J35<>""),Proses!H35,"") -> Praktikum Jaringan Komputer | I35: =IF(AND(Proses!$G35<>"",Proses!$H35<>"",Proses!$I35<>"",Proses!$J35<>""),Proses!I35,"") -> 1 | J35: =IF(AND(Proses!$G35<>"",Proses!$H35<>"",Proses!$I35<>"",Proses!$J35<>""),Proses!J35,"") -> AB
A36: 3 | B36: SI0306 | C36: Perancangan Web | D36: 4 | E36: =IF(AND($G36<>"",$H36<>"",$I36<>"",$J36<>""),$D36,"") -> 4 | F36: =IF(AND($G36<>"",$H36<>"",$I36<>"",$J36<>""),$J36,"") -> BC | G36: =IF(AND(Proses!$G36<>"",Proses!$H36<>"",Proses!$I36<>"",Proses!$J36<>""),Proses!G36,"") -> SI0306 | H36: =IF(AND(Proses!$G36<>"",Proses!$H36<>"",Proses!$I36<>"",Proses!$J36<>""),Proses!H36,"") -> Perancangan Web | I36: =IF(AND(Proses!$G36<>"",Proses!$H36<>"",Proses!$I36<>"",Proses!$J36<>""),Proses!I36,"") -> 4 | J36: =IF(AND(Proses!$G36<>"",Proses!$H36<>"",Proses!$I36<>"",Proses!$J36<>""),Proses!J36,"") -> BC
A37: 4 | B37: SI0211 | C37: Analisis dan Perancangan Sistem | D37: 4 | E37: =IF(AND($G37<>"",$H37<>"",$I37<>"",$J37<>""),$D37,"") | F37: =IF(AND($G37<>"",$H37<>"",$I37<>"",$J37<>""),$J37,"") | G37: =IF(AND(Proses!$G37<>"",Proses!$H37<>"",Proses!$I37<>"",Proses!$J37<>""),Proses!G37,"") | H37: =IF(AND(Proses!$G37<>"",Proses!$H37<>"",Proses!$I37<>"",Proses!$J37<>""),Proses!H37,"") | I37: =IF(AND(Proses!$G37<>"",Proses!$H37<>"",Proses!$I37<>"",Proses!$J37<>""),Proses!I37,"") | J37: =IF(AND(Proses!$G37<>"",Proses!$H37<>"",Proses!$I37<>"",Proses!$J37<>""),Proses!J37,"")
A38: 5 | B38: SI0307 | C38: Pemrograman Berorientasi Obyek | D38: 4 | E38: =IF(AND($G38<>"",$H38<>"",$I38<>"",$J38<>""),$D38,"") | F38: =IF(AND($G38<>"",$H38<>"",$I38<>"",$J38<>""),$J38,"") | G38: =IF(AND(Proses!$G38<>"",Proses!$H38<>"",Proses!$I38<>"",Proses!$J38<>""),Proses!G38,"") | H38: =IF(AND(Proses!$G38<>"",Proses!$H38<>"",Proses!$I38<>"",Proses!$J38<>""),Proses!H38,"") | I38: =IF(AND(Proses!$G38<>"",Proses!$H38<>"",Proses!$I38<>"",Proses!$J38<>""),Proses!I38,"") | J38: =IF(AND(Proses!$G38<>"",Proses!$H38<>"",Proses!$I38<>"",Proses!$J38<>""),Proses!J38,"")
A39: 6 | B39: SI0213 | C39: Sistem Operasi | D39: 2 | E39: =IF(AND($G39<>"",$H39<>"",$I39<>"",$J39<>""),$D39,"") | F39: =IF(AND($G39<>"",$H39<>"",$I39<>"",$J39<>""),$J39,"") | G39: =IF(AND(Proses!$G39<>"",Proses!$H39<>"",Proses!$I39<>"",Proses!$J39<>""),Proses!G39,"") | H39: =IF(AND(Proses!$G39<>"",Proses!$H39<>"",Proses!$I39<>"",Proses!$J39<>""),Proses!H39,"") | I39: =IF(AND(Proses!$G39<>"",Proses!$H39<>"",Proses!$I39<>"",Proses!$J39<>""),Proses!I39,"") | J39: =IF(AND(Proses!$G39<>"",Proses!$H39<>"",Proses!$I39<>"",Proses!$J39<>""),Proses!J39,"")
A40: 7 | B40: SI0217 | C40: Kalkulus | D40: 2 | E40: =IF(AND($G40<>"",$H40<>"",$I40<>"",$J40<>""),$D40,"") | F40: =IF(AND($G40<>"",$H40<>"",$I40<>"",$J40<>""),$J40,"") | G40: =IF(AND(Proses!$G40<>"",Proses!$H40<>"",Proses!$I40<>"",Proses!$J40<>""),Proses!G40,"") | H40: =IF(AND(Proses!$G40<>"",Proses!$H40<>"",Proses!$I40<>"",Proses!$J40<>""),Proses!H40,"") | I40: =IF(AND(Proses!$G40<>"",Proses!$H40<>"",Proses!$I40<>"",Proses!$J40<>""),Proses!I40,"") | J40: =IF(AND(Proses!$G40<>"",Proses!$H40<>"",Proses!$I40<>"",Proses!$J40<>""),Proses!J40,"")
A41: Total SKS | D41: =SUM(D34:D40) -> 19 | E41: =IF(Proses!E41 <>"",Proses!E41,"") -> 7 | F41: =IF(Proses!F41 <>"",Proses!F41,"") | G41: =IF(Proses!G41 <>"",Proses!G41,"") | H41: =IF(Proses!H41 <>"",Proses!H41,"") | I41: =IF(Proses!I41 <>"",Proses!I41,"") | J41: =IF(Proses!J41 <>"",Proses!J41,"")
A42: SEMESTER 4 | E42: =IF(Proses!E42 <>"",Proses!E42,"") | F42: =IF(Proses!F42 <>"",Proses!F42,"") | G42: =IF(Proses!G42 <>"",Proses!G42,"") | H42: =IF(Proses!H42 <>"",Proses!H42,"") | I42: =IF(Proses!I42 <>"",Proses!I42,"") | J42: =IF(Proses!J42 <>"",Proses!J42,"")
...

Sheet IS
A1: Hasil Transfer Nilai Sementara
A2: Program Studi Sistem Informasi ITB STIKOM Bali
A4: Nama Calon Mhs | C4: =Proses!C4 -> : I Made Oka Mahendra | F4: Prodi | H4: =Proses!H4 -> :Sistem Informasi
A5: Asal PT/Univ. | C5: =Proses!C5 -> : ITB STIKOM Bali | F5: Jenjang | H5: =Proses!H5 -> :ReNIM
A6: Fakultas | C6: =Proses!C6 -> : - | F6: Tgl. Proses | H6: =Proses!H6 -> : 6 Juli 2021
A7: ="Total SKS yang ditransfer : "&D81&" SKS" -> Total SKS yang ditransfer : 38 SKS
A9: Matakuliah ITB STIKOM Bali | G9: Matakuliah Asal
A10: NO | B10: KODE | C10: MATA KULIAH | D10: SKS | E10: SKS Diakui | F10: Nilai | G10: KODE | H10: MATA KULIAH | I10: SKS | J10: Nilai
A11: SEMESTER 1
A12: 1 | B12: SI9105 | C12: Bahasa Inggris I | D12: 2 | E12: =IF(AND($G12<>"",$H12<>"",$I12<>"",$J12<>""),$D12,"") -> 2 | F12: =IF(AND($G12<>"",$H12<>"",$I12<>"",$J12<>""),$J12,"") -> AB | G12: =IF(AND(Proses!$G12<>"",Proses!$H12<>"",Proses!$I12<>"",Proses!$J12<>""),Proses!G12,"") -> SI9105 | H12: =IF(AND(Proses!$G12<>"",Proses!$H12<>"",Proses!$I12<>"",Proses!$J12<>""),Proses!H12,"") -> Bahasa Inggris I | I12: =IF(AND(Proses!$G12<>"",Proses!$H12<>"",Proses!$I12<>"",Proses!$J12<>""),Proses!I12,"") -> 2 | J12: =IF(AND(Proses!$G12<>"",Proses!$H12<>"",Proses!$I12<>"",Proses!$J12<>""),Proses!J12,"") -> AB
A13: 2 | B13: SI9208 | C13: Seni dan Budaya | D13: 2 | E13: =IF(AND($G13<>"",$H13<>"",$I13<>"",$J13<>""),$D13,"") -> 2 | F13: =IF(AND($G13<>"",$H13<>"",$I13<>"",$J13<>""),$J13,"") -> A | G13: =IF(AND(Proses!$G13<>"",Proses!$H13<>"",Proses!$I13<>"",Proses!$J13<>""),Proses!G13,"") -> SI9208 | H13: =IF(AND(Proses!$G13<>"",Proses!$H13<>"",Proses!$I13<>"",Proses!$J13<>""),Proses!H13,"") -> Seni Budaya | I13: =IF(AND(Proses!$G13<>"",Proses!$H13<>"",Proses!$I13<>"",Proses!$J13<>""),Proses!I13,"") -> 2 | J13: =IF(AND(Proses!$G13<>"",Proses!$H13<>"",Proses!$I13<>"",Proses!$J13<>""),Proses!J13,"") -> A
A14: 3 | B14: SI0201 | C14: Matematika Diskrit | D14: 4 | E14: =IF(AND($G14<>"",$H14<>"",$I14<>"",$J14<>""),$D14,"") -> 4 | F14: =IF(AND($G14<>"",$H14<>"",$I14<>"",$J14<>""),$J14,"") -> AB | G14: =IF(AND(Proses!$G14<>"",Proses!$H14<>"",Proses!$I14<>"",Proses!$J14<>""),Proses!G14,"") -> SI0201 | H14: =IF(AND(Proses!$G14<>"",Proses!$H14<>"",Proses!$I14<>"",Proses!$J14<>""),Proses!H14,"") -> Matematika Diskrit | I14: =IF(AND(Proses!$G14<>"",Proses!$H14<>"",Proses!$I14<>"",Proses!$J14<>""),Proses!I14,"") -> 4 | J14: =IF(AND(Proses!$G14<>"",Proses!$H14<>"",Proses!$I14<>"",Proses!$J14<>""),Proses!J14,"") -> AB
A15: 4 | B15: SI0202 | C15: Algoritma dan Pemrograman | D15: 2 | E15: =IF(AND($G15<>"",$H15<>"",$I15<>"",$J15<>""),$D15,"") -> 2 | F15: =IF(AND($G15<>"",$H15<>"",$I15<>"",$J15<>""),$J15,"") -> AB | G15: =IF(AND(Proses!$G15<>"",Proses!$H15<>"",Proses!$I15<>"",Proses!$J15<>""),Proses!G15,"") -> SI0202 | H15: =IF(AND(Proses!$G15<>"",Proses!$H15<>"",Proses!$I15<>"",Proses!$J15<>""),Proses!H15,"") -> Algoritma dan Pemrograman | I15: =IF(AND(Proses!$G15<>"",Proses!$H15<>"",Proses!$I15<>"",Proses!$J15<>""),Proses!I15,"") -> 2 | J15: =IF(AND(Proses!$G15<>"",Proses!$H15<>"",Proses!$I15<>"",Proses!$J15<>""),Proses!J15,"") -> AB
A16: 5 | B16: SI0304 | C16: Praktikum Algoritma dan Pemrograman | D16: 1 | E16: =IF(AND($G16<>"",$H16<>"",$I16<>"",$J16<>""),$D16,"") -> 1 | F16: =IF(AND($G16<>"",$H16<>"",$I16<>"",$J16<>""),$J16,"") -> AB | G16: =IF(AND(Proses!$G16<>"",Proses!$H16<>"",Proses!$I16<>"",Proses!$J16<>""),Proses!G16,"") -> SI0304 | H16: =IF(AND(Proses!$G16<>"",Proses!$H16<>"",Proses!$I16<>"",Proses!$J16<>""),Proses!H16,"") -> Praktikum Algoritma dan Pemrograman | I16: =IF(AND(Proses!$G16<>"",Proses!$H16<>"",Proses!$I16<>"",Proses!$J16<>""),Proses!I16,"") -> 1 | J16: =IF(AND(Proses!$G16<>"",Proses!$H16<>"",Proses!$I16<>"",Proses!$J16<>""),Proses!J16,"") -> AB
A17: 6 | B17: SI9203 | C17: Pengantar Teknologi Informasi | D17: 2 | E17: =IF(AND($G17<>"",$H17<>"",$I17<>"",$J17<>""),$D17,"") -> 2 | F17: =IF(AND($G17<>"",$H17<>"",$I17<>"",$J17<>""),$J17,"") -> AB | G17: =IF(AND(Proses!$G17<>"",Proses!$H17<>"",Proses!$I17<>"",Proses!$J17<>""),Proses!G17,"") -> SI9203 | H17: =IF(AND(Proses!$G17<>"",Proses!$H17<>"",Proses!$I17<>"",Proses!$J17<>""),Proses!H17,"") -> Pengantar Teknologi Informasi | I17: =IF(AND(Proses!$G17<>"",Proses!$H17<>"",Proses!$I17<>"",Proses!$J17<>""),Proses!I17,"") -> 2 | J17: =IF(AND(Proses!$G17<>"",Proses!$H17<>"",Proses!$I17<>"",Proses!$J17<>""),Proses!J17,"") -> AB
A18: 7 | B18: SI9301 | C18: Praktikum Pengantar Teknologi Informasi | D18: 1 | E18: =IF(AND($G18<>"",$H18<>"",$I18<>"",$J18<>""),$D18,"") -> 1 | F18: =IF(AND($G18<>"",$H18<>"",$I18<>"",$J18<>""),$J18,"") -> B | G18: =IF(AND(Proses!$G18<>"",Proses!$H18<>"",Proses!$I18<>"",Proses!$J18<>""),Proses!G18,"") -> SI9301 | H18: =IF(AND(Proses!$G18<>"",Proses!$H18<>"",Proses!$I18<>"",Proses!$J18<>""),Proses!H18,"") -> Praktikum Pengantar Teknologi Informasi | I18: =IF(AND(Proses!$G18<>"",Proses!$H18<>"",Proses!$I18<>"",Proses!$J18<>""),Proses!I18,"") -> 1 | J18: =IF(AND(Proses!$G18<>"",Proses!$H18<>"",Proses!$I18<>"",Proses!$J18<>""),Proses!J18,"") -> B
A19: 8 | B19: SI0102 | C19: Pancasila | D19: 2 | E19: =IF(AND($G19<>"",$H19<>"",$I19<>"",$J19<>""),$D19,"") -> 2 | F19: =IF(AND($G19<>"",$H19<>"",$I19<>"",$J19<>""),$J19,"") -> A | G19: =IF(AND(Proses!$G19<>"",Proses!$H19<>"",Proses!$I19<>"",Proses!$J19<>""),Proses!G19,"") -> SI0102 | H19: =IF(AND(Proses!$G19<>"",Proses!$H19<>"",Proses!$I19<>"",Proses!$J19<>""),Proses!H19,"") -> Pancasila | I19: =IF(AND(Proses!$G19<>"",Proses!$H19<>"",Proses!$I19<>"",Proses!$J19<>""),Proses!I19,"") -> 2 | J19: =IF(AND(Proses!$G19<>"",Proses!$H19<>"",Proses!$I19<>"",Proses!$J19<>""),Proses!J19,"") -> A
A20: 9 | B20: SI0221 | C20: Konsep dan Aplikasi Sistem Informasi | D20: 2 | E20: =IF(AND($G20<>"",$H20<>"",$I20<>"",$J20<>""),$D20,"") | F20: =IF(AND($G20<>"",$H20<>"",$I20<>"",$J20<>""),$J20,"") | G20: =IF(AND(Proses!$G20<>"",Proses!$H20<>"",Proses!$I20<>"",Proses!$J20<>""),Proses!G20,"") | H20: =IF(AND(Proses!$G20<>"",Proses!$H20<>"",Proses!$I20<>"",Proses!$J20<>""),Proses!H20,"") | I20: =IF(AND(Proses!$G20<>"",Proses!$H20<>"",Proses!$I20<>"",Proses!$J20<>""),Proses!I20,"") | J20: =IF(AND(Proses!$G20<>"",Proses!$H20<>"",Proses!$I20<>"",Proses!$J20<>""),Proses!J20,"")
A21: Total SKS | D21: =SUM(D12:D20) -> 18 | E21: =IF(Proses!E21 <>"",Proses!E21,"") -> 16 | F21: =IF(Proses!F21 <>"",Proses!F21,"") | G21: =IF(Proses!G21 <>"",Proses!G21,"") | H21: =IF(Proses!H21 <>"",Proses!H21,"") | I21: =IF(Proses!I21 <>"",Proses!I21,"") | J21: =IF(Proses!J21 <>"",Proses!J21,"")
A22: SEMESTER 2 | E22: =IF(Proses!E22 <>"",Proses!E22,"") | F22: =IF(Proses!F22 <>"",Proses!F22,"") | G22: =IF(Proses!G22 <>"",Proses!G22,"") | H22: =IF(Proses!H22 <>"",Proses!H22,"") | I22: =IF(Proses!I22 <>"",Proses!I22,"") | J22: =IF(Proses!J22 <>"",Proses!J22,"")
A23: 1 | B23: SI0204 | C23: Komunikasi Data | D23: 4 | E23: =IF(AND($G23<>"",$H23<>"",$I23<>"",$J23<>""),$D23,"") -> 4 | F23: =IF(AND($G23<>"",$H23<>"",$I23<>"",$J23<>""),$J23,"") -> C | G23: =IF(AND(Proses!$G23<>"",Proses!$H23<>"",Proses!$I23<>"",Proses!$J23<>""),Proses!G23,"") -> SI0204 | H23: =IF(AND(Proses!$G23<>"",Proses!$H23<>"",Proses!$I23<>"",Proses!$J23<>""),Proses!H23,"") -> Komunikasi Data | I23: =IF(AND(Proses!$G23<>"",Proses!$H23<>"",Proses!$I23<>"",Proses!$J23<>""),Proses!I23,"") -> 4 | J23: =IF(AND(Proses!$G23<>"",Proses!$H23<>"",Proses!$I23<>"",Proses!$J23<>""),Proses!J23,"") -> C
A24: 2 | B24: SI0205 | C24: Basis Data | D24: 2 | E24: =IF(AND($G24<>"",$H24<>"",$I24<>"",$J24<>""),$D24,"") -> 2 | F24: =IF(AND($G24<>"",$H24<>"",$I24<>"",$J24<>""),$J24,"") -> B | G24: =IF(AND(Proses!$G24<>"",Proses!$H24<>"",Proses!$I24<>"",Proses!$J24<>""),Proses!G24,"") -> SI0205 | H24: =IF(AND(Proses!$G24<>"",Proses!$H24<>"",Proses!$I24<>"",Proses!$J24<>""),Proses!H24,"") -> Basis Data | I24: =IF(AND(Proses!$G24<>"",Proses!$H24<>"",Proses!$I24<>"",Proses!$J24<>""),Proses!I24,"") -> 2 | J24: =IF(AND(Proses!$G24<>"",Proses!$H24<>"",Proses!$I24<>"",Proses!$J24<>""),Proses!J24,"") -> B
A25: 3 | B25: SI0302 | C25: Praktikum Basis data | D25: 1 | E25: =IF(AND($G25<>"",$H25<>"",$I25<>"",$J25<>""),$D25,"") | F25: =IF(AND($G25<>"",$H25<>"",$I25<>"",$J25<>""),$J25,"") | G25: =IF(AND(Proses!$G25<>"",Proses!$H25<>"",Proses!$I25<>"",Proses!$J25<>""),Proses!G25,"") | H25: =IF(AND(Proses!$G25<>"",Proses!$H25<>"",Proses!$I25<>"",Proses!$J25<>""),Proses!H25,"") | I25: =IF(AND(Proses!$G25<>"",Proses!$H25<>"",Proses!$I25<>"",Proses!$J25<>""),Proses!I25,"") | J25: =IF(AND(Proses!$G25<>"",Proses!$H25<>"",Proses!$I25<>"",Proses!$J25<>""),Proses!J25,"")
A26: 4 | B26: SI0206 | C26: Struktur Data | D26: 2 | E26: =IF(AND($G26<>"",$H26<>"",$I26<>"",$J26<>""),$D26,"") -> 2 | F26: =IF(AND($G26<>"",$H26<>"",$I26<>"",$J26<>""),$J26,"") -> A | G26: =IF(AND(Proses!$G26<>"",Proses!$H26<>"",Proses!$I26<>"",Proses!$J26<>""),Proses!G26,"") -> SI0206 | H26: =IF(AND(Proses!$G26<>"",Proses!$H26<>"",Proses!$I26<>"",Proses!$J26<>""),Proses!H26,"") -> Struktur Data | I26: =IF(AND(Proses!$G26<>"",Proses!$H26<>"",Proses!$I26<>"",Proses!$J26<>""),Proses!I26,"") -> 2 | J26: =IF(AND(Proses!$G26<>"",Proses!$H26<>"",Proses!$I26<>"",Proses!$J26<>""),Proses!J26,"") -> A
A27: 5 | B27: SI0303 | C27: Praktikum Struktur Data | D27: 1 | E27: =IF(AND($G27<>"",$H27<>"",$I27<>"",$J27<>""),$D27,"") -> 1 | F27: =IF(AND($G27<>"",$H27<>"",$I27<>"",$J27<>""),$J27,"") -> C | G27: =IF(AND(Proses!$G27<>"",Proses!$H27<>"",Proses!$I27<>"",Proses!$J27<>""),Proses!G27,"") -> SI0303 | H27: =IF(AND(Proses!$G27<>"",Proses!$H27<>"",Proses!$I27<>"",Proses!$J27<>""),Proses!H27,"") -> Praktikum Struktur Data | I27: =IF(AND(Proses!$G27<>"",Proses!$H27<>"",Proses!$I27<>"",Proses!$J27<>""),Proses!I27,"") -> 1 | J27: =IF(AND(Proses!$G27<>"",Proses!$H27<>"",Proses!$I27<>"",Proses!$J27<>""),Proses!J27,"") -> C
A28: 6 | B28: SI9207 | C28: Organisasi Komputer | D28: 2 | E28: =IF(AND($G28<>"",$H28<>"",$I28<>"",$J28<>""),$D28,"") -> 2 | F28: =IF(AND($G28<>"",$H28<>"",$I28<>"",$J28<>""),$J28,"") -> C | G28: =IF(AND(Proses!$G28<>"",Proses!$H28<>"",Proses!$I28<>"",Proses!$J28<>""),Proses!G28,"") -> SI9207 | H28: =IF(AND(Proses!$G28<>"",Proses!$H28<>"",Proses!$I28<>"",Proses!$J28<>""),Proses!H28,"") -> Organisasi Komputer | I28: =IF(AND(Proses!$G28<>"",Proses!$H28<>"",Proses!$I28<>"",Proses!$J28<>""),Proses!I28,"") -> 2 | J28: =IF(AND(Proses!$G28<>"",Proses!$H28<>"",Proses!$I28<>"",Proses!$J28<>""),Proses!J28,"") -> C
A29: 7 | B29: SI9106 | C29: Bahasa Inggris II | D29: 2 | E29: =IF(AND($G29<>"",$H29<>"",$I29<>"",$J29<>""),$D29,"") | F29: =IF(AND($G29<>"",$H29<>"",$I29<>"",$J29<>""),$J29,"") | G29: =IF(AND(Proses!$G29<>"",Proses!$H29<>"",Proses!$I29<>"",Proses!$J29<>""),Proses!G29,"") | H29: =IF(AND(Proses!$G29<>"",Proses!$H29<>"",Proses!$I29<>"",Proses!$J29<>""),Proses!H29,"") | I29: =IF(AND(Proses!$G29<>"",Proses!$H29<>"",Proses!$I29<>"",Proses!$J29<>""),Proses!I29,"") | J29: =IF(AND(Proses!$G29<>"",Proses!$H29<>"",Proses!$I29<>"",Proses!$J29<>""),Proses!J29,"")
A30: 8 | B30: SI0103 | C30: Kewarganegaraan | D30: 2 | E30: =IF(AND($G30<>"",$H30<>"",$I30<>"",$J30<>""),$D30,"") | F30: =IF(AND($G30<>"",$H30<>"",$I30<>"",$J30<>""),$J30,"") | G30: =IF(AND(Proses!$G30<>"",Proses!$H30<>"",Proses!$I30<>"",Proses!$J30<>""),Proses!G30,"") | H30: =IF(AND(Proses!$G30<>"",Proses!$H30<>"",Proses!$I30<>"",Proses!$J30<>""),Proses!H30,"") | I30: =IF(AND(Proses!$G30<>"",Proses!$H30<>"",Proses!$I30<>"",Proses!$J30<>""),Proses!I30,"") | J30: =IF(AND(Proses!$G30<>"",Proses!$H30<>"",Proses!$I30<>"",Proses!$J30<>""),Proses!J30,"")
A31: 9 | B31: SI0101 | C31: Pendidikan Agama | D31: 2 | E31: =IF(AND($G31<>"",$H31<>"",$I31<>"",$J31<>""),$D31,"") | F31: =IF(AND($G31<>"",$H31<>"",$I31<>"",$J31<>""),$J31,"") | G31: =IF(AND(Proses!$G31<>"",Proses!$H31<>"",Proses!$I31<>"",Proses!$J31<>""),Proses!G31,"") | H31: =IF(AND(Proses!$G31<>"",Proses!$H31<>"",Proses!$I31<>"",Proses!$J31<>""),Proses!H31,"") | I31: =IF(AND(Proses!$G31<>"",Proses!$H31<>"",Proses!$I31<>"",Proses!$J31<>""),Proses!I31,"") | J31: =IF(AND(Proses!$G31<>"",Proses!$H31<>"",Proses!$I31<>"",Proses!$J31<>""),Proses!J31,"")
A32: Total SKS | D32: =SUM(D23:D31) -> 18 | E32: =IF(Proses!E32 <>"",Proses!E32,"") -> 11 | F32: =IF(Proses!F32 <>"",Proses!F32,"") | G32: =IF(Proses!G32 <>"",Proses!G32,"") | H32: =IF(Proses!H32 <>"",Proses!H32,"") | I32: =IF(Proses!I32 <>"",Proses!I32,"") | J32: =IF(Proses!J32 <>"",Proses!J32,"")
A33: SEMESTER 3 | E33: =IF(Proses!E33 <>"",Proses!E33,"") | F33: =IF(Proses!F33 <>"",Proses!F33,"") | G33: =IF(Proses!G33 <>"",Proses!G33,"") | H33: =IF(Proses!H33 <>"",Proses!H33,"") | I33: =IF(Proses!I33 <>"",Proses!I33,"") | J33: =IF(Proses!J33 <>"",Proses!J33,"")
A34: 1 | B34: SI0209 | C34: Jaringan Komputer | D34: 2 | E34: =IF(AND($G34<>"",$H34<>"",$I34<>"",$J34<>""),$D34,"") -> 2 | F34: =IF(AND($G34<>"",$H34<>"",$I34<>"",$J34<>""),$J34,"") -> BC | G34: =IF(AND(Proses!$G34<>"",Proses!$H34<>"",Proses!$I34<>"",Proses!$J34<>""),Proses!G34,"") -> SI0209 | H34: =IF(AND(Proses!$G34<>"",Proses!$H34<>"",Proses!$I34<>"",Proses!$J34<>""),Proses!H34,"") -> Jaringan Komputer | I34: =IF(AND(Proses!$G34<>"",Proses!$H34<>"",Proses!$I34<>"",Proses!$J34<>""),Proses!I34,"") -> 2 | J34: =IF(AND(Proses!$G34<>"",Proses!$H34<>"",Proses!$I34<>"",Proses!$J34<>""),Proses!J34,"") -> BC
A35: 2 | B35: SI0305 | C35: Praktikum Jaringan Komputer | D35: 1 | E35: =IF(AND($G35<>"",$H35<>"",$I35<>"",$J35<>""),$D35,"") -> 1 | F35: =IF(AND($G35<>"",$H35<>"",$I35<>"",$J35<>""),$J35,"") -> AB | G35: =IF(AND(Proses!$G35<>"",Proses!$H35<>"",Proses!$I35<>"",Proses!$J35<>""),Proses!G35,"") -> SI0305 | H35: =IF(AND(Proses!$G35<>"",Proses!$H35<>"",Proses!$I35<>"",Proses!$J35<>""),Proses!H35,"") -> Praktikum Jaringan Komputer | I35: =IF(AND(Proses!$G35<>"",Proses!$H35<>"",Proses!$I35<>"",Proses!$J35<>""),Proses!I35,"") -> 1 | J35: =IF(AND(Proses!$G35<>"",Proses!$H35<>"",Proses!$I35<>"",Proses!$J35<>""),Proses!J35,"") -> AB
A36: 3 | B36: SI0306 | C36: Perancangan Web | D36: 4 | E36: =IF(AND($G36<>"",$H36<>"",$I36<>"",$J36<>""),$D36,"") -> 4 | F36: =IF(AND($G36<>"",$H36<>"",$I36<>"",$J36<>""),$J36,"") -> BC | G36: =IF(AND(Proses!$G36<>"",Proses!$H36<>"",Proses!$I36<>"",Proses!$J36<>""),Proses!G36,"") -> SI0306 | H36: =IF(AND(Proses!$G36<>"",Proses!$H36<>"",Proses!$I36<>"",Proses!$J36<>""),Proses!H36,"") -> Perancangan Web | I36: =IF(AND(Proses!$G36<>"",Proses!$H36<>"",Proses!$I36<>"",Proses!$J36<>""),Proses!I36,"") -> 4 | J36: =IF(AND(Proses!$G36<>"",Proses!$H36<>"",Proses!$I36<>"",Proses!$J36<>""),Proses!J36,"") -> BC
A37: 4 | B37: SI0211 | C37: Analisis dan Perancangan Sistem | D37: 4 | E37: =IF(AND($G37<>"",$H37<>"",$I37<>"",$J37<>""),$D37,"") | F37: =IF(AND($G37<>"",$H37<>"",$I37<>"",$J37<>""),$J37,"") | G37: =IF(AND(Proses!$G37<>"",Proses!$H37<>"",Proses!$I37<>"",Proses!$J37<>""),Proses!G37,"") | H37: =IF(AND(Proses!$G37<>"",Proses!$H37<>"",Proses!$I37<>"",Proses!$J37<>""),Proses!H37,"") | I37: =IF(AND(Proses!$G37<>"",Proses!$H37<>"",Proses!$I37<>"",Proses!$J37<>""),Proses!I37,"") | J37: =IF(AND(Proses!$G37<>"",Proses!$H37<>"",Proses!$I37<>"",Proses!$J37<>""),Proses!J37,"")
A38: 5 | B38: SI0307 | C38: Pemrograman Berorientasi Obyek | D38: 4 | E38: =IF(AND($G38<>"",$H38<>"",$I38<>"",$J38<>""),$D38,"") | F38: =IF(AND($G38<>"",$H38<>"",$I38<>"",$J38<>""),$J38,"") | G38: =IF(AND(Proses!$G38<>"",Proses!$H38<>"",Proses!$I38<>"",Proses!$J38<>""),Proses!G38,"") | H38: =IF(AND(Proses!$G38<>"",Proses!$H38<>"",Proses!$I38<>"",Proses!$J38<>""),Proses!H38,"") | I38: =IF(AND(Proses!$G38<>"",Proses!$H38<>"",Proses!$I38<>"",Proses!$J38<>""),Proses!I38,"") | J38: =IF(AND(Proses!$G38<>"",Proses!$H38<>"",Proses!$I38<>"",Proses!$J38<>""),Proses!J38,"")
A39: 6 | B39: SI0213 | C39: Sistem Operasi | D39: 2 | E39: =IF(AND($G39<>"",$H39<>"",$I39<>"",$J39<>""),$D39,"") | F39: =IF(AND($G39<>"",$H39<>"",$I39<>"",$J39<>""),$J39,"") | G39: =IF(AND(Proses!$G39<>"",Proses!$H39<>"",Proses!$I39<>"",Proses!$J39<>""),Proses!G39,"") | H39: =IF(AND(Proses!$G39<>"",Proses!$H39<>"",Proses!$I39<>"",Proses!$J39<>""),Proses!H39,"") | I39: =IF(AND(Proses!$G39<>"",Proses!$H39<>"",Proses!$I39<>"",Proses!$J39<>""),Proses!I39,"") | J39: =IF(AND(Proses!$G39<>"",Proses!$H39<>"",Proses!$I39<>"",Proses!$J39<>""),Proses!J39,"")
A40: 7 | B40: SI0217 | C40: Kalkulus | D40: 2 | E40: =IF(AND($G40<>"",$H40<>"",$I40<>"",$J40<>""),$D40,"") | F40: =IF(AND($G40<>"",$H40<>"",$I40<>"",$J40<>""),$J40,"") | G40: =IF(AND(Proses!$G40<>"",Proses!$H40<>"",Proses!$I40<>"",Proses!$J40<>""),Proses!G40,"") | H40: =IF(AND(Proses!$G40<>"",Proses!$H40<>"",Proses!$I40<>"",Proses!$J40<>""),Proses!H40,"") | I40: =IF(AND(Proses!$G40<>"",Proses!$H40<>"",Proses!$I40<>"",Proses!$J40<>""),Proses!I40,"") | J40: =IF(AND(Proses!$G40<>"",Proses!$H40<>"",Proses!$I40<>"",Proses!$J40<>""),Proses!J40,"")
A41: Total SKS | D41: =SUM(D34:D40) -> 19 | E41: =IF(Proses!E41 <>"",Proses!E41,"") -> 7 | F41: =IF(Proses!F41 <>"",Proses!F41,"") | G41: =IF(Proses!G41 <>"",Proses!G41,"") | H41: =IF(Proses!H41 <>"",Proses!H41,"") | I41: =IF(Proses!I41 <>"",Proses!I41,"") | J41: =IF(Proses!J41 <>"",Proses!J41,"")
A42: SEMESTER 4 | E42: =IF(Proses!E42 <>"",Proses!E42,"") | F42: =IF(Proses!F42 <>"",Proses!F42,"") | G42: =IF(Proses!G42 <>"",Proses!G42,"") | H42: =IF(Proses!H42 <>"",Proses!H42,"") | I42: =IF(Proses!I42 <>"",Proses!I42,"") | J42: =IF(Proses!J42 <>"",Proses!J42,"")
...
